[2025-02-16 08:26:14] [INFO    ] discord.client: logging in using static token
[2025-02-16 08:26:14] [INFO    ] discord.gateway: Shard ID None has connected to Gateway (Session ID: d38cb83d48b1cab2db289d891c93c186).
Atyiseusseatyiseuss!
session_stats.txt does not exist.
Task exception was never retrieved
future: <Task finished name='discord.py: on_message' coro=<Client._run_event() done, defined at /home/lucassukeunkim/myenv/lib/python3.11/site-packages/discord/client.py:441> exception=SystemExit()>
Traceback (most recent call last):
  File "/home/lucassukeunkim/myenv/lib/python3.11/site-packages/discord/client.py", line 869, in run
    asyncio.run(runner())
  File "/usr/lib/python3.11/asyncio/runners.py", line 190, in run
    return runner.run(main)
           ^^^^^^^^^^^^^^^^
  File "/usr/lib/python3.11/asyncio/runners.py", line 118, in run
    return self._loop.run_until_complete(task)
           ^^^^^^^^^^^^^^^^^^^^^^^^^^^^^^^^^^^
  File "/usr/lib/python3.11/asyncio/base_events.py", line 640, in run_until_complete
    self.run_forever()
  File "/usr/lib/python3.11/asyncio/base_events.py", line 607, in run_forever
    self._run_once()
  File "/usr/lib/python3.11/asyncio/base_events.py", line 1922, in _run_once
    handle._run()
  File "/usr/lib/python3.11/asyncio/events.py", line 80, in _run
    self._context.run(self._callback, *self._args)
  File "/home/lucassukeunkim/myenv/lib/python3.11/site-packages/discord/client.py", line 449, in _run_event
    await coro(*args, **kwargs)
  File "/home/lucassukeunkim/scuffed_discord_bot/bot.py", line 48, in on_message
    await bot.process_commands(message)
  File "/home/lucassukeunkim/myenv/lib/python3.11/site-packages/discord/ext/commands/bot.py", line 1408, in process_commands
    await self.invoke(ctx)  # type: ignore
    ^^^^^^^^^^^^^^^^^^^^^^
  File "/home/lucassukeunkim/myenv/lib/python3.11/site-packages/discord/ext/commands/bot.py", line 1366, in invoke
    await ctx.command.invoke(ctx)
  File "/home/lucassukeunkim/myenv/lib/python3.11/site-packages/discord/ext/commands/core.py", line 1029, in invoke
    await injected(*ctx.args, **ctx.kwargs)  # type: ignore
    ^^^^^^^^^^^^^^^^^^^^^^^^^^^^^^^^^^^^^^^
  File "/home/lucassukeunkim/myenv/lib/python3.11/site-packages/discord/ext/commands/core.py", line 235, in wrapped
    ret = await coro(*args, **kwargs)
          ^^^^^^^^^^^^^^^^^^^^^^^^^^^
  File "/home/lucassukeunkim/scuffed_discord_bot/bot.py", line 640, in restart
    sys.exit()
SystemExit
[2025-02-16 08:26:50] [INFO    ] discord.client: logging in using static token
[2025-02-16 08:26:51] [INFO    ] discord.gateway: Shard ID None has connected to Gateway (Session ID: 2d40acff59502c2d9111bce3ae32b21f).
[2025-02-16 08:28:23] [WARNING ] discord.gateway: Shard ID None heartbeat blocked for more than 10 seconds.
Loop thread traceback (most recent call last):
  File "/home/lucassukeunkim/scuffed_discord_bot/bot.py", line 682, in <module>
    bot.run(BOT_TOKEN, reconnect=True)
  File "/home/lucassukeunkim/myenv/lib/python3.11/site-packages/discord/client.py", line 869, in run
    asyncio.run(runner())
  File "/usr/lib/python3.11/asyncio/runners.py", line 190, in run
    return runner.run(main)
  File "/usr/lib/python3.11/asyncio/runners.py", line 118, in run
    return self._loop.run_until_complete(task)
  File "/usr/lib/python3.11/asyncio/base_events.py", line 640, in run_until_complete
    self.run_forever()
  File "/usr/lib/python3.11/asyncio/base_events.py", line 607, in run_forever
    self._run_once()
  File "/usr/lib/python3.11/asyncio/base_events.py", line 1922, in _run_once
    handle._run()
  File "/usr/lib/python3.11/asyncio/events.py", line 80, in _run
    self._context.run(self._callback, *self._args)
  File "/home/lucassukeunkim/myenv/lib/python3.11/site-packages/discord/client.py", line 449, in _run_event
    await coro(*args, **kwargs)
  File "/home/lucassukeunkim/scuffed_discord_bot/bot.py", line 48, in on_message
    await bot.process_commands(message)
  File "/home/lucassukeunkim/myenv/lib/python3.11/site-packages/discord/ext/commands/bot.py", line 1408, in process_commands
    await self.invoke(ctx)  # type: ignore
  File "/home/lucassukeunkim/myenv/lib/python3.11/site-packages/discord/ext/commands/bot.py", line 1366, in invoke
    await ctx.command.invoke(ctx)
  File "/home/lucassukeunkim/myenv/lib/python3.11/site-packages/discord/ext/commands/core.py", line 1029, in invoke
    await injected(*ctx.args, **ctx.kwargs)  # type: ignore
  File "/home/lucassukeunkim/myenv/lib/python3.11/site-packages/discord/ext/commands/core.py", line 235, in wrapped
    ret = await coro(*args, **kwargs)
  File "/home/lucassukeunkim/scuffed_discord_bot/bot.py", line 580, in pushtextfiles
    subprocess.run(["git", "fetch"], check=True)
  File "/usr/lib/python3.11/subprocess.py", line 550, in run
    stdout, stderr = process.communicate(input, timeout=timeout)
  File "/usr/lib/python3.11/subprocess.py", line 1199, in communicate
    self.wait()
  File "/usr/lib/python3.11/subprocess.py", line 1262, in wait
    return self._wait(timeout=timeout)
  File "/usr/lib/python3.11/subprocess.py", line 1997, in _wait
    (pid, sts) = self._try_wait(0)
  File "/usr/lib/python3.11/subprocess.py", line 1955, in _try_wait
    (pid, sts) = os.waitpid(self.pid, wait_flags)

[2025-02-16 08:28:33] [WARNING ] discord.gateway: Shard ID None heartbeat blocked for more than 20 seconds.
Loop thread traceback (most recent call last):
  File "/home/lucassukeunkim/scuffed_discord_bot/bot.py", line 682, in <module>
    bot.run(BOT_TOKEN, reconnect=True)
  File "/home/lucassukeunkim/myenv/lib/python3.11/site-packages/discord/client.py", line 869, in run
    asyncio.run(runner())
  File "/usr/lib/python3.11/asyncio/runners.py", line 190, in run
    return runner.run(main)
  File "/usr/lib/python3.11/asyncio/runners.py", line 118, in run
    return self._loop.run_until_complete(task)
  File "/usr/lib/python3.11/asyncio/base_events.py", line 640, in run_until_complete
    self.run_forever()
  File "/usr/lib/python3.11/asyncio/base_events.py", line 607, in run_forever
    self._run_once()
  File "/usr/lib/python3.11/asyncio/base_events.py", line 1922, in _run_once
    handle._run()
  File "/usr/lib/python3.11/asyncio/events.py", line 80, in _run
    self._context.run(self._callback, *self._args)
  File "/home/lucassukeunkim/myenv/lib/python3.11/site-packages/discord/client.py", line 449, in _run_event
    await coro(*args, **kwargs)
  File "/home/lucassukeunkim/scuffed_discord_bot/bot.py", line 48, in on_message
    await bot.process_commands(message)
  File "/home/lucassukeunkim/myenv/lib/python3.11/site-packages/discord/ext/commands/bot.py", line 1408, in process_commands
    await self.invoke(ctx)  # type: ignore
  File "/home/lucassukeunkim/myenv/lib/python3.11/site-packages/discord/ext/commands/bot.py", line 1366, in invoke
    await ctx.command.invoke(ctx)
  File "/home/lucassukeunkim/myenv/lib/python3.11/site-packages/discord/ext/commands/core.py", line 1029, in invoke
    await injected(*ctx.args, **ctx.kwargs)  # type: ignore
  File "/home/lucassukeunkim/myenv/lib/python3.11/site-packages/discord/ext/commands/core.py", line 235, in wrapped
    ret = await coro(*args, **kwargs)
  File "/home/lucassukeunkim/scuffed_discord_bot/bot.py", line 580, in pushtextfiles
    subprocess.run(["git", "fetch"], check=True)
  File "/usr/lib/python3.11/subprocess.py", line 550, in run
    stdout, stderr = process.communicate(input, timeout=timeout)
  File "/usr/lib/python3.11/subprocess.py", line 1199, in communicate
    self.wait()
  File "/usr/lib/python3.11/subprocess.py", line 1262, in wait
    return self._wait(timeout=timeout)
  File "/usr/lib/python3.11/subprocess.py", line 1997, in _wait
    (pid, sts) = self._try_wait(0)
  File "/usr/lib/python3.11/subprocess.py", line 1955, in _try_wait
    (pid, sts) = os.waitpid(self.pid, wait_flags)

[2025-02-16 08:28:43] [WARNING ] discord.gateway: Shard ID None heartbeat blocked for more than 30 seconds.
Loop thread traceback (most recent call last):
  File "/home/lucassukeunkim/scuffed_discord_bot/bot.py", line 682, in <module>
    bot.run(BOT_TOKEN, reconnect=True)
  File "/home/lucassukeunkim/myenv/lib/python3.11/site-packages/discord/client.py", line 869, in run
    asyncio.run(runner())
  File "/usr/lib/python3.11/asyncio/runners.py", line 190, in run
    return runner.run(main)
  File "/usr/lib/python3.11/asyncio/runners.py", line 118, in run
    return self._loop.run_until_complete(task)
  File "/usr/lib/python3.11/asyncio/base_events.py", line 640, in run_until_complete
    self.run_forever()
  File "/usr/lib/python3.11/asyncio/base_events.py", line 607, in run_forever
    self._run_once()
  File "/usr/lib/python3.11/asyncio/base_events.py", line 1922, in _run_once
    handle._run()
  File "/usr/lib/python3.11/asyncio/events.py", line 80, in _run
    self._context.run(self._callback, *self._args)
  File "/home/lucassukeunkim/myenv/lib/python3.11/site-packages/discord/client.py", line 449, in _run_event
    await coro(*args, **kwargs)
  File "/home/lucassukeunkim/scuffed_discord_bot/bot.py", line 48, in on_message
    await bot.process_commands(message)
  File "/home/lucassukeunkim/myenv/lib/python3.11/site-packages/discord/ext/commands/bot.py", line 1408, in process_commands
    await self.invoke(ctx)  # type: ignore
  File "/home/lucassukeunkim/myenv/lib/python3.11/site-packages/discord/ext/commands/bot.py", line 1366, in invoke
    await ctx.command.invoke(ctx)
  File "/home/lucassukeunkim/myenv/lib/python3.11/site-packages/discord/ext/commands/core.py", line 1029, in invoke
    await injected(*ctx.args, **ctx.kwargs)  # type: ignore
  File "/home/lucassukeunkim/myenv/lib/python3.11/site-packages/discord/ext/commands/core.py", line 235, in wrapped
    ret = await coro(*args, **kwargs)
  File "/home/lucassukeunkim/scuffed_discord_bot/bot.py", line 580, in pushtextfiles
    subprocess.run(["git", "fetch"], check=True)
  File "/usr/lib/python3.11/subprocess.py", line 550, in run
    stdout, stderr = process.communicate(input, timeout=timeout)
  File "/usr/lib/python3.11/subprocess.py", line 1199, in communicate
    self.wait()
  File "/usr/lib/python3.11/subprocess.py", line 1262, in wait
    return self._wait(timeout=timeout)
  File "/usr/lib/python3.11/subprocess.py", line 1997, in _wait
    (pid, sts) = self._try_wait(0)
  File "/usr/lib/python3.11/subprocess.py", line 1955, in _try_wait
    (pid, sts) = os.waitpid(self.pid, wait_flags)

[2025-02-16 08:28:53] [WARNING ] discord.gateway: Shard ID None heartbeat blocked for more than 40 seconds.
Loop thread traceback (most recent call last):
  File "/home/lucassukeunkim/scuffed_discord_bot/bot.py", line 682, in <module>
    bot.run(BOT_TOKEN, reconnect=True)
  File "/home/lucassukeunkim/myenv/lib/python3.11/site-packages/discord/client.py", line 869, in run
    asyncio.run(runner())
  File "/usr/lib/python3.11/asyncio/runners.py", line 190, in run
    return runner.run(main)
  File "/usr/lib/python3.11/asyncio/runners.py", line 118, in run
    return self._loop.run_until_complete(task)
  File "/usr/lib/python3.11/asyncio/base_events.py", line 640, in run_until_complete
    self.run_forever()
  File "/usr/lib/python3.11/asyncio/base_events.py", line 607, in run_forever
    self._run_once()
  File "/usr/lib/python3.11/asyncio/base_events.py", line 1922, in _run_once
    handle._run()
  File "/usr/lib/python3.11/asyncio/events.py", line 80, in _run
    self._context.run(self._callback, *self._args)
  File "/home/lucassukeunkim/myenv/lib/python3.11/site-packages/discord/client.py", line 449, in _run_event
    await coro(*args, **kwargs)
  File "/home/lucassukeunkim/scuffed_discord_bot/bot.py", line 48, in on_message
    await bot.process_commands(message)
  File "/home/lucassukeunkim/myenv/lib/python3.11/site-packages/discord/ext/commands/bot.py", line 1408, in process_commands
    await self.invoke(ctx)  # type: ignore
  File "/home/lucassukeunkim/myenv/lib/python3.11/site-packages/discord/ext/commands/bot.py", line 1366, in invoke
    await ctx.command.invoke(ctx)
  File "/home/lucassukeunkim/myenv/lib/python3.11/site-packages/discord/ext/commands/core.py", line 1029, in invoke
    await injected(*ctx.args, **ctx.kwargs)  # type: ignore
  File "/home/lucassukeunkim/myenv/lib/python3.11/site-packages/discord/ext/commands/core.py", line 235, in wrapped
    ret = await coro(*args, **kwargs)
  File "/home/lucassukeunkim/scuffed_discord_bot/bot.py", line 580, in pushtextfiles
    subprocess.run(["git", "fetch"], check=True)
  File "/usr/lib/python3.11/subprocess.py", line 550, in run
    stdout, stderr = process.communicate(input, timeout=timeout)
  File "/usr/lib/python3.11/subprocess.py", line 1199, in communicate
    self.wait()
  File "/usr/lib/python3.11/subprocess.py", line 1262, in wait
    return self._wait(timeout=timeout)
  File "/usr/lib/python3.11/subprocess.py", line 1997, in _wait
    (pid, sts) = self._try_wait(0)
  File "/usr/lib/python3.11/subprocess.py", line 1955, in _try_wait
    (pid, sts) = os.waitpid(self.pid, wait_flags)

[2025-02-16 08:29:03] [WARNING ] discord.gateway: Shard ID None heartbeat blocked for more than 50 seconds.
Loop thread traceback (most recent call last):
  File "/home/lucassukeunkim/scuffed_discord_bot/bot.py", line 682, in <module>
    bot.run(BOT_TOKEN, reconnect=True)
  File "/home/lucassukeunkim/myenv/lib/python3.11/site-packages/discord/client.py", line 869, in run
    asyncio.run(runner())
  File "/usr/lib/python3.11/asyncio/runners.py", line 190, in run
    return runner.run(main)
  File "/usr/lib/python3.11/asyncio/runners.py", line 118, in run
    return self._loop.run_until_complete(task)
  File "/usr/lib/python3.11/asyncio/base_events.py", line 640, in run_until_complete
    self.run_forever()
  File "/usr/lib/python3.11/asyncio/base_events.py", line 607, in run_forever
    self._run_once()
  File "/usr/lib/python3.11/asyncio/base_events.py", line 1922, in _run_once
    handle._run()
  File "/usr/lib/python3.11/asyncio/events.py", line 80, in _run
    self._context.run(self._callback, *self._args)
  File "/home/lucassukeunkim/myenv/lib/python3.11/site-packages/discord/client.py", line 449, in _run_event
    await coro(*args, **kwargs)
  File "/home/lucassukeunkim/scuffed_discord_bot/bot.py", line 48, in on_message
    await bot.process_commands(message)
  File "/home/lucassukeunkim/myenv/lib/python3.11/site-packages/discord/ext/commands/bot.py", line 1408, in process_commands
    await self.invoke(ctx)  # type: ignore
  File "/home/lucassukeunkim/myenv/lib/python3.11/site-packages/discord/ext/commands/bot.py", line 1366, in invoke
    await ctx.command.invoke(ctx)
  File "/home/lucassukeunkim/myenv/lib/python3.11/site-packages/discord/ext/commands/core.py", line 1029, in invoke
    await injected(*ctx.args, **ctx.kwargs)  # type: ignore
  File "/home/lucassukeunkim/myenv/lib/python3.11/site-packages/discord/ext/commands/core.py", line 235, in wrapped
    ret = await coro(*args, **kwargs)
  File "/home/lucassukeunkim/scuffed_discord_bot/bot.py", line 580, in pushtextfiles
    subprocess.run(["git", "fetch"], check=True)
  File "/usr/lib/python3.11/subprocess.py", line 550, in run
    stdout, stderr = process.communicate(input, timeout=timeout)
  File "/usr/lib/python3.11/subprocess.py", line 1199, in communicate
    self.wait()
  File "/usr/lib/python3.11/subprocess.py", line 1262, in wait
    return self._wait(timeout=timeout)
  File "/usr/lib/python3.11/subprocess.py", line 1997, in _wait
    (pid, sts) = self._try_wait(0)
  File "/usr/lib/python3.11/subprocess.py", line 1955, in _try_wait
    (pid, sts) = os.waitpid(self.pid, wait_flags)

[2025-02-16 08:29:13] [WARNING ] discord.gateway: Shard ID None heartbeat blocked for more than 60 seconds.
Loop thread traceback (most recent call last):
  File "/home/lucassukeunkim/scuffed_discord_bot/bot.py", line 682, in <module>
    bot.run(BOT_TOKEN, reconnect=True)
  File "/home/lucassukeunkim/myenv/lib/python3.11/site-packages/discord/client.py", line 869, in run
    asyncio.run(runner())
  File "/usr/lib/python3.11/asyncio/runners.py", line 190, in run
    return runner.run(main)
  File "/usr/lib/python3.11/asyncio/runners.py", line 118, in run
    return self._loop.run_until_complete(task)
  File "/usr/lib/python3.11/asyncio/base_events.py", line 640, in run_until_complete
    self.run_forever()
  File "/usr/lib/python3.11/asyncio/base_events.py", line 607, in run_forever
    self._run_once()
  File "/usr/lib/python3.11/asyncio/base_events.py", line 1922, in _run_once
    handle._run()
  File "/usr/lib/python3.11/asyncio/events.py", line 80, in _run
    self._context.run(self._callback, *self._args)
  File "/home/lucassukeunkim/myenv/lib/python3.11/site-packages/discord/client.py", line 449, in _run_event
    await coro(*args, **kwargs)
  File "/home/lucassukeunkim/scuffed_discord_bot/bot.py", line 48, in on_message
    await bot.process_commands(message)
  File "/home/lucassukeunkim/myenv/lib/python3.11/site-packages/discord/ext/commands/bot.py", line 1408, in process_commands
    await self.invoke(ctx)  # type: ignore
  File "/home/lucassukeunkim/myenv/lib/python3.11/site-packages/discord/ext/commands/bot.py", line 1366, in invoke
    await ctx.command.invoke(ctx)
  File "/home/lucassukeunkim/myenv/lib/python3.11/site-packages/discord/ext/commands/core.py", line 1029, in invoke
    await injected(*ctx.args, **ctx.kwargs)  # type: ignore
  File "/home/lucassukeunkim/myenv/lib/python3.11/site-packages/discord/ext/commands/core.py", line 235, in wrapped
    ret = await coro(*args, **kwargs)
  File "/home/lucassukeunkim/scuffed_discord_bot/bot.py", line 580, in pushtextfiles
    subprocess.run(["git", "fetch"], check=True)
  File "/usr/lib/python3.11/subprocess.py", line 550, in run
    stdout, stderr = process.communicate(input, timeout=timeout)
  File "/usr/lib/python3.11/subprocess.py", line 1199, in communicate
    self.wait()
  File "/usr/lib/python3.11/subprocess.py", line 1262, in wait
    return self._wait(timeout=timeout)
  File "/usr/lib/python3.11/subprocess.py", line 1997, in _wait
    (pid, sts) = self._try_wait(0)
  File "/usr/lib/python3.11/subprocess.py", line 1955, in _try_wait
    (pid, sts) = os.waitpid(self.pid, wait_flags)

[2025-02-16 08:29:23] [WARNING ] discord.gateway: Shard ID None heartbeat blocked for more than 70 seconds.
Loop thread traceback (most recent call last):
  File "/home/lucassukeunkim/scuffed_discord_bot/bot.py", line 682, in <module>
    bot.run(BOT_TOKEN, reconnect=True)
  File "/home/lucassukeunkim/myenv/lib/python3.11/site-packages/discord/client.py", line 869, in run
    asyncio.run(runner())
  File "/usr/lib/python3.11/asyncio/runners.py", line 190, in run
    return runner.run(main)
  File "/usr/lib/python3.11/asyncio/runners.py", line 118, in run
    return self._loop.run_until_complete(task)
  File "/usr/lib/python3.11/asyncio/base_events.py", line 640, in run_until_complete
    self.run_forever()
  File "/usr/lib/python3.11/asyncio/base_events.py", line 607, in run_forever
    self._run_once()
  File "/usr/lib/python3.11/asyncio/base_events.py", line 1922, in _run_once
    handle._run()
  File "/usr/lib/python3.11/asyncio/events.py", line 80, in _run
    self._context.run(self._callback, *self._args)
  File "/home/lucassukeunkim/myenv/lib/python3.11/site-packages/discord/client.py", line 449, in _run_event
    await coro(*args, **kwargs)
  File "/home/lucassukeunkim/scuffed_discord_bot/bot.py", line 48, in on_message
    await bot.process_commands(message)
  File "/home/lucassukeunkim/myenv/lib/python3.11/site-packages/discord/ext/commands/bot.py", line 1408, in process_commands
    await self.invoke(ctx)  # type: ignore
  File "/home/lucassukeunkim/myenv/lib/python3.11/site-packages/discord/ext/commands/bot.py", line 1366, in invoke
    await ctx.command.invoke(ctx)
  File "/home/lucassukeunkim/myenv/lib/python3.11/site-packages/discord/ext/commands/core.py", line 1029, in invoke
    await injected(*ctx.args, **ctx.kwargs)  # type: ignore
  File "/home/lucassukeunkim/myenv/lib/python3.11/site-packages/discord/ext/commands/core.py", line 235, in wrapped
    ret = await coro(*args, **kwargs)
  File "/home/lucassukeunkim/scuffed_discord_bot/bot.py", line 580, in pushtextfiles
    subprocess.run(["git", "fetch"], check=True)
  File "/usr/lib/python3.11/subprocess.py", line 550, in run
    stdout, stderr = process.communicate(input, timeout=timeout)
  File "/usr/lib/python3.11/subprocess.py", line 1199, in communicate
    self.wait()
  File "/usr/lib/python3.11/subprocess.py", line 1262, in wait
    return self._wait(timeout=timeout)
  File "/usr/lib/python3.11/subprocess.py", line 1997, in _wait
    (pid, sts) = self._try_wait(0)
  File "/usr/lib/python3.11/subprocess.py", line 1955, in _try_wait
    (pid, sts) = os.waitpid(self.pid, wait_flags)

[2025-02-16 08:29:33] [WARNING ] discord.gateway: Shard ID None heartbeat blocked for more than 80 seconds.
Loop thread traceback (most recent call last):
  File "/home/lucassukeunkim/scuffed_discord_bot/bot.py", line 682, in <module>
    bot.run(BOT_TOKEN, reconnect=True)
  File "/home/lucassukeunkim/myenv/lib/python3.11/site-packages/discord/client.py", line 869, in run
    asyncio.run(runner())
  File "/usr/lib/python3.11/asyncio/runners.py", line 190, in run
    return runner.run(main)
  File "/usr/lib/python3.11/asyncio/runners.py", line 118, in run
    return self._loop.run_until_complete(task)
  File "/usr/lib/python3.11/asyncio/base_events.py", line 640, in run_until_complete
    self.run_forever()
  File "/usr/lib/python3.11/asyncio/base_events.py", line 607, in run_forever
    self._run_once()
  File "/usr/lib/python3.11/asyncio/base_events.py", line 1922, in _run_once
    handle._run()
  File "/usr/lib/python3.11/asyncio/events.py", line 80, in _run
    self._context.run(self._callback, *self._args)
  File "/home/lucassukeunkim/myenv/lib/python3.11/site-packages/discord/client.py", line 449, in _run_event
    await coro(*args, **kwargs)
  File "/home/lucassukeunkim/scuffed_discord_bot/bot.py", line 48, in on_message
    await bot.process_commands(message)
  File "/home/lucassukeunkim/myenv/lib/python3.11/site-packages/discord/ext/commands/bot.py", line 1408, in process_commands
    await self.invoke(ctx)  # type: ignore
  File "/home/lucassukeunkim/myenv/lib/python3.11/site-packages/discord/ext/commands/bot.py", line 1366, in invoke
    await ctx.command.invoke(ctx)
  File "/home/lucassukeunkim/myenv/lib/python3.11/site-packages/discord/ext/commands/core.py", line 1029, in invoke
    await injected(*ctx.args, **ctx.kwargs)  # type: ignore
  File "/home/lucassukeunkim/myenv/lib/python3.11/site-packages/discord/ext/commands/core.py", line 235, in wrapped
    ret = await coro(*args, **kwargs)
  File "/home/lucassukeunkim/scuffed_discord_bot/bot.py", line 580, in pushtextfiles
    subprocess.run(["git", "fetch"], check=True)
  File "/usr/lib/python3.11/subprocess.py", line 550, in run
    stdout, stderr = process.communicate(input, timeout=timeout)
  File "/usr/lib/python3.11/subprocess.py", line 1199, in communicate
    self.wait()
  File "/usr/lib/python3.11/subprocess.py", line 1262, in wait
    return self._wait(timeout=timeout)
  File "/usr/lib/python3.11/subprocess.py", line 1997, in _wait
    (pid, sts) = self._try_wait(0)
  File "/usr/lib/python3.11/subprocess.py", line 1955, in _try_wait
    (pid, sts) = os.waitpid(self.pid, wait_flags)

[2025-02-16 08:29:43] [WARNING ] discord.gateway: Shard ID None heartbeat blocked for more than 90 seconds.
Loop thread traceback (most recent call last):
  File "/home/lucassukeunkim/scuffed_discord_bot/bot.py", line 682, in <module>
    bot.run(BOT_TOKEN, reconnect=True)
  File "/home/lucassukeunkim/myenv/lib/python3.11/site-packages/discord/client.py", line 869, in run
    asyncio.run(runner())
  File "/usr/lib/python3.11/asyncio/runners.py", line 190, in run
    return runner.run(main)
  File "/usr/lib/python3.11/asyncio/runners.py", line 118, in run
    return self._loop.run_until_complete(task)
  File "/usr/lib/python3.11/asyncio/base_events.py", line 640, in run_until_complete
    self.run_forever()
  File "/usr/lib/python3.11/asyncio/base_events.py", line 607, in run_forever
    self._run_once()
  File "/usr/lib/python3.11/asyncio/base_events.py", line 1922, in _run_once
    handle._run()
  File "/usr/lib/python3.11/asyncio/events.py", line 80, in _run
    self._context.run(self._callback, *self._args)
  File "/home/lucassukeunkim/myenv/lib/python3.11/site-packages/discord/client.py", line 449, in _run_event
    await coro(*args, **kwargs)
  File "/home/lucassukeunkim/scuffed_discord_bot/bot.py", line 48, in on_message
    await bot.process_commands(message)
  File "/home/lucassukeunkim/myenv/lib/python3.11/site-packages/discord/ext/commands/bot.py", line 1408, in process_commands
    await self.invoke(ctx)  # type: ignore
  File "/home/lucassukeunkim/myenv/lib/python3.11/site-packages/discord/ext/commands/bot.py", line 1366, in invoke
    await ctx.command.invoke(ctx)
  File "/home/lucassukeunkim/myenv/lib/python3.11/site-packages/discord/ext/commands/core.py", line 1029, in invoke
    await injected(*ctx.args, **ctx.kwargs)  # type: ignore
  File "/home/lucassukeunkim/myenv/lib/python3.11/site-packages/discord/ext/commands/core.py", line 235, in wrapped
    ret = await coro(*args, **kwargs)
  File "/home/lucassukeunkim/scuffed_discord_bot/bot.py", line 580, in pushtextfiles
    subprocess.run(["git", "fetch"], check=True)
  File "/usr/lib/python3.11/subprocess.py", line 550, in run
    stdout, stderr = process.communicate(input, timeout=timeout)
  File "/usr/lib/python3.11/subprocess.py", line 1199, in communicate
    self.wait()
  File "/usr/lib/python3.11/subprocess.py", line 1262, in wait
    return self._wait(timeout=timeout)
  File "/usr/lib/python3.11/subprocess.py", line 1997, in _wait
    (pid, sts) = self._try_wait(0)
  File "/usr/lib/python3.11/subprocess.py", line 1955, in _try_wait
    (pid, sts) = os.waitpid(self.pid, wait_flags)

[2025-02-16 08:29:53] [WARNING ] discord.gateway: Shard ID None heartbeat blocked for more than 100 seconds.
Loop thread traceback (most recent call last):
  File "/home/lucassukeunkim/scuffed_discord_bot/bot.py", line 682, in <module>
    bot.run(BOT_TOKEN, reconnect=True)
  File "/home/lucassukeunkim/myenv/lib/python3.11/site-packages/discord/client.py", line 869, in run
    asyncio.run(runner())
  File "/usr/lib/python3.11/asyncio/runners.py", line 190, in run
    return runner.run(main)
  File "/usr/lib/python3.11/asyncio/runners.py", line 118, in run
    return self._loop.run_until_complete(task)
  File "/usr/lib/python3.11/asyncio/base_events.py", line 640, in run_until_complete
    self.run_forever()
  File "/usr/lib/python3.11/asyncio/base_events.py", line 607, in run_forever
    self._run_once()
  File "/usr/lib/python3.11/asyncio/base_events.py", line 1922, in _run_once
    handle._run()
  File "/usr/lib/python3.11/asyncio/events.py", line 80, in _run
    self._context.run(self._callback, *self._args)
  File "/home/lucassukeunkim/myenv/lib/python3.11/site-packages/discord/client.py", line 449, in _run_event
    await coro(*args, **kwargs)
  File "/home/lucassukeunkim/scuffed_discord_bot/bot.py", line 48, in on_message
    await bot.process_commands(message)
  File "/home/lucassukeunkim/myenv/lib/python3.11/site-packages/discord/ext/commands/bot.py", line 1408, in process_commands
    await self.invoke(ctx)  # type: ignore
  File "/home/lucassukeunkim/myenv/lib/python3.11/site-packages/discord/ext/commands/bot.py", line 1366, in invoke
    await ctx.command.invoke(ctx)
  File "/home/lucassukeunkim/myenv/lib/python3.11/site-packages/discord/ext/commands/core.py", line 1029, in invoke
    await injected(*ctx.args, **ctx.kwargs)  # type: ignore
  File "/home/lucassukeunkim/myenv/lib/python3.11/site-packages/discord/ext/commands/core.py", line 235, in wrapped
    ret = await coro(*args, **kwargs)
  File "/home/lucassukeunkim/scuffed_discord_bot/bot.py", line 580, in pushtextfiles
    subprocess.run(["git", "fetch"], check=True)
  File "/usr/lib/python3.11/subprocess.py", line 550, in run
    stdout, stderr = process.communicate(input, timeout=timeout)
  File "/usr/lib/python3.11/subprocess.py", line 1199, in communicate
    self.wait()
  File "/usr/lib/python3.11/subprocess.py", line 1262, in wait
    return self._wait(timeout=timeout)
  File "/usr/lib/python3.11/subprocess.py", line 1997, in _wait
    (pid, sts) = self._try_wait(0)
  File "/usr/lib/python3.11/subprocess.py", line 1955, in _try_wait
    (pid, sts) = os.waitpid(self.pid, wait_flags)

[2025-02-16 08:30:03] [WARNING ] discord.gateway: Shard ID None heartbeat blocked for more than 110 seconds.
Loop thread traceback (most recent call last):
  File "/home/lucassukeunkim/scuffed_discord_bot/bot.py", line 682, in <module>
    bot.run(BOT_TOKEN, reconnect=True)
  File "/home/lucassukeunkim/myenv/lib/python3.11/site-packages/discord/client.py", line 869, in run
    asyncio.run(runner())
  File "/usr/lib/python3.11/asyncio/runners.py", line 190, in run
    return runner.run(main)
  File "/usr/lib/python3.11/asyncio/runners.py", line 118, in run
    return self._loop.run_until_complete(task)
  File "/usr/lib/python3.11/asyncio/base_events.py", line 640, in run_until_complete
    self.run_forever()
  File "/usr/lib/python3.11/asyncio/base_events.py", line 607, in run_forever
    self._run_once()
  File "/usr/lib/python3.11/asyncio/base_events.py", line 1922, in _run_once
    handle._run()
  File "/usr/lib/python3.11/asyncio/events.py", line 80, in _run
    self._context.run(self._callback, *self._args)
  File "/home/lucassukeunkim/myenv/lib/python3.11/site-packages/discord/client.py", line 449, in _run_event
    await coro(*args, **kwargs)
  File "/home/lucassukeunkim/scuffed_discord_bot/bot.py", line 48, in on_message
    await bot.process_commands(message)
  File "/home/lucassukeunkim/myenv/lib/python3.11/site-packages/discord/ext/commands/bot.py", line 1408, in process_commands
    await self.invoke(ctx)  # type: ignore
  File "/home/lucassukeunkim/myenv/lib/python3.11/site-packages/discord/ext/commands/bot.py", line 1366, in invoke
    await ctx.command.invoke(ctx)
  File "/home/lucassukeunkim/myenv/lib/python3.11/site-packages/discord/ext/commands/core.py", line 1029, in invoke
    await injected(*ctx.args, **ctx.kwargs)  # type: ignore
  File "/home/lucassukeunkim/myenv/lib/python3.11/site-packages/discord/ext/commands/core.py", line 235, in wrapped
    ret = await coro(*args, **kwargs)
  File "/home/lucassukeunkim/scuffed_discord_bot/bot.py", line 580, in pushtextfiles
    subprocess.run(["git", "fetch"], check=True)
  File "/usr/lib/python3.11/subprocess.py", line 550, in run
    stdout, stderr = process.communicate(input, timeout=timeout)
  File "/usr/lib/python3.11/subprocess.py", line 1199, in communicate
    self.wait()
  File "/usr/lib/python3.11/subprocess.py", line 1262, in wait
    return self._wait(timeout=timeout)
  File "/usr/lib/python3.11/subprocess.py", line 1997, in _wait
    (pid, sts) = self._try_wait(0)
  File "/usr/lib/python3.11/subprocess.py", line 1955, in _try_wait
    (pid, sts) = os.waitpid(self.pid, wait_flags)

[2025-02-16 08:30:13] [WARNING ] discord.gateway: Shard ID None heartbeat blocked for more than 120 seconds.
Loop thread traceback (most recent call last):
  File "/home/lucassukeunkim/scuffed_discord_bot/bot.py", line 682, in <module>
    bot.run(BOT_TOKEN, reconnect=True)
  File "/home/lucassukeunkim/myenv/lib/python3.11/site-packages/discord/client.py", line 869, in run
    asyncio.run(runner())
  File "/usr/lib/python3.11/asyncio/runners.py", line 190, in run
    return runner.run(main)
  File "/usr/lib/python3.11/asyncio/runners.py", line 118, in run
    return self._loop.run_until_complete(task)
  File "/usr/lib/python3.11/asyncio/base_events.py", line 640, in run_until_complete
    self.run_forever()
  File "/usr/lib/python3.11/asyncio/base_events.py", line 607, in run_forever
    self._run_once()
  File "/usr/lib/python3.11/asyncio/base_events.py", line 1922, in _run_once
    handle._run()
  File "/usr/lib/python3.11/asyncio/events.py", line 80, in _run
    self._context.run(self._callback, *self._args)
  File "/home/lucassukeunkim/myenv/lib/python3.11/site-packages/discord/client.py", line 449, in _run_event
    await coro(*args, **kwargs)
  File "/home/lucassukeunkim/scuffed_discord_bot/bot.py", line 48, in on_message
    await bot.process_commands(message)
  File "/home/lucassukeunkim/myenv/lib/python3.11/site-packages/discord/ext/commands/bot.py", line 1408, in process_commands
    await self.invoke(ctx)  # type: ignore
  File "/home/lucassukeunkim/myenv/lib/python3.11/site-packages/discord/ext/commands/bot.py", line 1366, in invoke
    await ctx.command.invoke(ctx)
  File "/home/lucassukeunkim/myenv/lib/python3.11/site-packages/discord/ext/commands/core.py", line 1029, in invoke
    await injected(*ctx.args, **ctx.kwargs)  # type: ignore
  File "/home/lucassukeunkim/myenv/lib/python3.11/site-packages/discord/ext/commands/core.py", line 235, in wrapped
    ret = await coro(*args, **kwargs)
  File "/home/lucassukeunkim/scuffed_discord_bot/bot.py", line 580, in pushtextfiles
    subprocess.run(["git", "fetch"], check=True)
  File "/usr/lib/python3.11/subprocess.py", line 550, in run
    stdout, stderr = process.communicate(input, timeout=timeout)
  File "/usr/lib/python3.11/subprocess.py", line 1199, in communicate
    self.wait()
  File "/usr/lib/python3.11/subprocess.py", line 1262, in wait
    return self._wait(timeout=timeout)
  File "/usr/lib/python3.11/subprocess.py", line 1997, in _wait
    (pid, sts) = self._try_wait(0)
  File "/usr/lib/python3.11/subprocess.py", line 1955, in _try_wait
    (pid, sts) = os.waitpid(self.pid, wait_flags)

[2025-02-16 08:30:23] [WARNING ] discord.gateway: Shard ID None heartbeat blocked for more than 130 seconds.
Loop thread traceback (most recent call last):
  File "/home/lucassukeunkim/scuffed_discord_bot/bot.py", line 682, in <module>
    bot.run(BOT_TOKEN, reconnect=True)
  File "/home/lucassukeunkim/myenv/lib/python3.11/site-packages/discord/client.py", line 869, in run
    asyncio.run(runner())
  File "/usr/lib/python3.11/asyncio/runners.py", line 190, in run
    return runner.run(main)
  File "/usr/lib/python3.11/asyncio/runners.py", line 118, in run
    return self._loop.run_until_complete(task)
  File "/usr/lib/python3.11/asyncio/base_events.py", line 640, in run_until_complete
    self.run_forever()
  File "/usr/lib/python3.11/asyncio/base_events.py", line 607, in run_forever
    self._run_once()
  File "/usr/lib/python3.11/asyncio/base_events.py", line 1922, in _run_once
    handle._run()
  File "/usr/lib/python3.11/asyncio/events.py", line 80, in _run
    self._context.run(self._callback, *self._args)
  File "/home/lucassukeunkim/myenv/lib/python3.11/site-packages/discord/client.py", line 449, in _run_event
    await coro(*args, **kwargs)
  File "/home/lucassukeunkim/scuffed_discord_bot/bot.py", line 48, in on_message
    await bot.process_commands(message)
  File "/home/lucassukeunkim/myenv/lib/python3.11/site-packages/discord/ext/commands/bot.py", line 1408, in process_commands
    await self.invoke(ctx)  # type: ignore
  File "/home/lucassukeunkim/myenv/lib/python3.11/site-packages/discord/ext/commands/bot.py", line 1366, in invoke
    await ctx.command.invoke(ctx)
  File "/home/lucassukeunkim/myenv/lib/python3.11/site-packages/discord/ext/commands/core.py", line 1029, in invoke
    await injected(*ctx.args, **ctx.kwargs)  # type: ignore
  File "/home/lucassukeunkim/myenv/lib/python3.11/site-packages/discord/ext/commands/core.py", line 235, in wrapped
    ret = await coro(*args, **kwargs)
  File "/home/lucassukeunkim/scuffed_discord_bot/bot.py", line 580, in pushtextfiles
    subprocess.run(["git", "fetch"], check=True)
  File "/usr/lib/python3.11/subprocess.py", line 550, in run
    stdout, stderr = process.communicate(input, timeout=timeout)
  File "/usr/lib/python3.11/subprocess.py", line 1199, in communicate
    self.wait()
  File "/usr/lib/python3.11/subprocess.py", line 1262, in wait
    return self._wait(timeout=timeout)
  File "/usr/lib/python3.11/subprocess.py", line 1997, in _wait
    (pid, sts) = self._try_wait(0)
  File "/usr/lib/python3.11/subprocess.py", line 1955, in _try_wait
    (pid, sts) = os.waitpid(self.pid, wait_flags)

[2025-02-16 08:30:33] [WARNING ] discord.gateway: Shard ID None heartbeat blocked for more than 140 seconds.
Loop thread traceback (most recent call last):
  File "/home/lucassukeunkim/scuffed_discord_bot/bot.py", line 682, in <module>
    bot.run(BOT_TOKEN, reconnect=True)
  File "/home/lucassukeunkim/myenv/lib/python3.11/site-packages/discord/client.py", line 869, in run
    asyncio.run(runner())
  File "/usr/lib/python3.11/asyncio/runners.py", line 190, in run
    return runner.run(main)
  File "/usr/lib/python3.11/asyncio/runners.py", line 118, in run
    return self._loop.run_until_complete(task)
  File "/usr/lib/python3.11/asyncio/base_events.py", line 640, in run_until_complete
    self.run_forever()
  File "/usr/lib/python3.11/asyncio/base_events.py", line 607, in run_forever
    self._run_once()
  File "/usr/lib/python3.11/asyncio/base_events.py", line 1922, in _run_once
    handle._run()
  File "/usr/lib/python3.11/asyncio/events.py", line 80, in _run
    self._context.run(self._callback, *self._args)
  File "/home/lucassukeunkim/myenv/lib/python3.11/site-packages/discord/client.py", line 449, in _run_event
    await coro(*args, **kwargs)
  File "/home/lucassukeunkim/scuffed_discord_bot/bot.py", line 48, in on_message
    await bot.process_commands(message)
  File "/home/lucassukeunkim/myenv/lib/python3.11/site-packages/discord/ext/commands/bot.py", line 1408, in process_commands
    await self.invoke(ctx)  # type: ignore
  File "/home/lucassukeunkim/myenv/lib/python3.11/site-packages/discord/ext/commands/bot.py", line 1366, in invoke
    await ctx.command.invoke(ctx)
  File "/home/lucassukeunkim/myenv/lib/python3.11/site-packages/discord/ext/commands/core.py", line 1029, in invoke
    await injected(*ctx.args, **ctx.kwargs)  # type: ignore
  File "/home/lucassukeunkim/myenv/lib/python3.11/site-packages/discord/ext/commands/core.py", line 235, in wrapped
    ret = await coro(*args, **kwargs)
  File "/home/lucassukeunkim/scuffed_discord_bot/bot.py", line 580, in pushtextfiles
    subprocess.run(["git", "fetch"], check=True)
  File "/usr/lib/python3.11/subprocess.py", line 550, in run
    stdout, stderr = process.communicate(input, timeout=timeout)
  File "/usr/lib/python3.11/subprocess.py", line 1199, in communicate
    self.wait()
  File "/usr/lib/python3.11/subprocess.py", line 1262, in wait
    return self._wait(timeout=timeout)
  File "/usr/lib/python3.11/subprocess.py", line 1997, in _wait
    (pid, sts) = self._try_wait(0)
  File "/usr/lib/python3.11/subprocess.py", line 1955, in _try_wait
    (pid, sts) = os.waitpid(self.pid, wait_flags)

[2025-02-16 08:30:43] [WARNING ] discord.gateway: Shard ID None heartbeat blocked for more than 150 seconds.
Loop thread traceback (most recent call last):
  File "/home/lucassukeunkim/scuffed_discord_bot/bot.py", line 682, in <module>
    bot.run(BOT_TOKEN, reconnect=True)
  File "/home/lucassukeunkim/myenv/lib/python3.11/site-packages/discord/client.py", line 869, in run
    asyncio.run(runner())
  File "/usr/lib/python3.11/asyncio/runners.py", line 190, in run
    return runner.run(main)
  File "/usr/lib/python3.11/asyncio/runners.py", line 118, in run
    return self._loop.run_until_complete(task)
  File "/usr/lib/python3.11/asyncio/base_events.py", line 640, in run_until_complete
    self.run_forever()
  File "/usr/lib/python3.11/asyncio/base_events.py", line 607, in run_forever
    self._run_once()
  File "/usr/lib/python3.11/asyncio/base_events.py", line 1922, in _run_once
    handle._run()
  File "/usr/lib/python3.11/asyncio/events.py", line 80, in _run
    self._context.run(self._callback, *self._args)
  File "/home/lucassukeunkim/myenv/lib/python3.11/site-packages/discord/client.py", line 449, in _run_event
    await coro(*args, **kwargs)
  File "/home/lucassukeunkim/scuffed_discord_bot/bot.py", line 48, in on_message
    await bot.process_commands(message)
  File "/home/lucassukeunkim/myenv/lib/python3.11/site-packages/discord/ext/commands/bot.py", line 1408, in process_commands
    await self.invoke(ctx)  # type: ignore
  File "/home/lucassukeunkim/myenv/lib/python3.11/site-packages/discord/ext/commands/bot.py", line 1366, in invoke
    await ctx.command.invoke(ctx)
  File "/home/lucassukeunkim/myenv/lib/python3.11/site-packages/discord/ext/commands/core.py", line 1029, in invoke
    await injected(*ctx.args, **ctx.kwargs)  # type: ignore
  File "/home/lucassukeunkim/myenv/lib/python3.11/site-packages/discord/ext/commands/core.py", line 235, in wrapped
    ret = await coro(*args, **kwargs)
  File "/home/lucassukeunkim/scuffed_discord_bot/bot.py", line 580, in pushtextfiles
    subprocess.run(["git", "fetch"], check=True)
  File "/usr/lib/python3.11/subprocess.py", line 550, in run
    stdout, stderr = process.communicate(input, timeout=timeout)
  File "/usr/lib/python3.11/subprocess.py", line 1199, in communicate
    self.wait()
  File "/usr/lib/python3.11/subprocess.py", line 1262, in wait
    return self._wait(timeout=timeout)
  File "/usr/lib/python3.11/subprocess.py", line 1997, in _wait
    (pid, sts) = self._try_wait(0)
  File "/usr/lib/python3.11/subprocess.py", line 1955, in _try_wait
    (pid, sts) = os.waitpid(self.pid, wait_flags)

[2025-02-16 08:30:53] [WARNING ] discord.gateway: Shard ID None heartbeat blocked for more than 160 seconds.
Loop thread traceback (most recent call last):
  File "/home/lucassukeunkim/scuffed_discord_bot/bot.py", line 682, in <module>
    bot.run(BOT_TOKEN, reconnect=True)
  File "/home/lucassukeunkim/myenv/lib/python3.11/site-packages/discord/client.py", line 869, in run
    asyncio.run(runner())
  File "/usr/lib/python3.11/asyncio/runners.py", line 190, in run
    return runner.run(main)
  File "/usr/lib/python3.11/asyncio/runners.py", line 118, in run
    return self._loop.run_until_complete(task)
  File "/usr/lib/python3.11/asyncio/base_events.py", line 640, in run_until_complete
    self.run_forever()
  File "/usr/lib/python3.11/asyncio/base_events.py", line 607, in run_forever
    self._run_once()
  File "/usr/lib/python3.11/asyncio/base_events.py", line 1922, in _run_once
    handle._run()
  File "/usr/lib/python3.11/asyncio/events.py", line 80, in _run
    self._context.run(self._callback, *self._args)
  File "/home/lucassukeunkim/myenv/lib/python3.11/site-packages/discord/client.py", line 449, in _run_event
    await coro(*args, **kwargs)
  File "/home/lucassukeunkim/scuffed_discord_bot/bot.py", line 48, in on_message
    await bot.process_commands(message)
  File "/home/lucassukeunkim/myenv/lib/python3.11/site-packages/discord/ext/commands/bot.py", line 1408, in process_commands
    await self.invoke(ctx)  # type: ignore
  File "/home/lucassukeunkim/myenv/lib/python3.11/site-packages/discord/ext/commands/bot.py", line 1366, in invoke
    await ctx.command.invoke(ctx)
  File "/home/lucassukeunkim/myenv/lib/python3.11/site-packages/discord/ext/commands/core.py", line 1029, in invoke
    await injected(*ctx.args, **ctx.kwargs)  # type: ignore
  File "/home/lucassukeunkim/myenv/lib/python3.11/site-packages/discord/ext/commands/core.py", line 235, in wrapped
    ret = await coro(*args, **kwargs)
  File "/home/lucassukeunkim/scuffed_discord_bot/bot.py", line 580, in pushtextfiles
    subprocess.run(["git", "fetch"], check=True)
  File "/usr/lib/python3.11/subprocess.py", line 550, in run
    stdout, stderr = process.communicate(input, timeout=timeout)
  File "/usr/lib/python3.11/subprocess.py", line 1199, in communicate
    self.wait()
  File "/usr/lib/python3.11/subprocess.py", line 1262, in wait
    return self._wait(timeout=timeout)
  File "/usr/lib/python3.11/subprocess.py", line 1997, in _wait
    (pid, sts) = self._try_wait(0)
  File "/usr/lib/python3.11/subprocess.py", line 1955, in _try_wait
    (pid, sts) = os.waitpid(self.pid, wait_flags)

[2025-02-16 08:31:03] [WARNING ] discord.gateway: Shard ID None heartbeat blocked for more than 170 seconds.
Loop thread traceback (most recent call last):
  File "/home/lucassukeunkim/scuffed_discord_bot/bot.py", line 682, in <module>
    bot.run(BOT_TOKEN, reconnect=True)
  File "/home/lucassukeunkim/myenv/lib/python3.11/site-packages/discord/client.py", line 869, in run
    asyncio.run(runner())
  File "/usr/lib/python3.11/asyncio/runners.py", line 190, in run
    return runner.run(main)
  File "/usr/lib/python3.11/asyncio/runners.py", line 118, in run
    return self._loop.run_until_complete(task)
  File "/usr/lib/python3.11/asyncio/base_events.py", line 640, in run_until_complete
    self.run_forever()
  File "/usr/lib/python3.11/asyncio/base_events.py", line 607, in run_forever
    self._run_once()
  File "/usr/lib/python3.11/asyncio/base_events.py", line 1922, in _run_once
    handle._run()
  File "/usr/lib/python3.11/asyncio/events.py", line 80, in _run
    self._context.run(self._callback, *self._args)
  File "/home/lucassukeunkim/myenv/lib/python3.11/site-packages/discord/client.py", line 449, in _run_event
    await coro(*args, **kwargs)
  File "/home/lucassukeunkim/scuffed_discord_bot/bot.py", line 48, in on_message
    await bot.process_commands(message)
  File "/home/lucassukeunkim/myenv/lib/python3.11/site-packages/discord/ext/commands/bot.py", line 1408, in process_commands
    await self.invoke(ctx)  # type: ignore
  File "/home/lucassukeunkim/myenv/lib/python3.11/site-packages/discord/ext/commands/bot.py", line 1366, in invoke
    await ctx.command.invoke(ctx)
  File "/home/lucassukeunkim/myenv/lib/python3.11/site-packages/discord/ext/commands/core.py", line 1029, in invoke
    await injected(*ctx.args, **ctx.kwargs)  # type: ignore
  File "/home/lucassukeunkim/myenv/lib/python3.11/site-packages/discord/ext/commands/core.py", line 235, in wrapped
    ret = await coro(*args, **kwargs)
  File "/home/lucassukeunkim/scuffed_discord_bot/bot.py", line 580, in pushtextfiles
    subprocess.run(["git", "fetch"], check=True)
  File "/usr/lib/python3.11/subprocess.py", line 550, in run
    stdout, stderr = process.communicate(input, timeout=timeout)
  File "/usr/lib/python3.11/subprocess.py", line 1199, in communicate
    self.wait()
  File "/usr/lib/python3.11/subprocess.py", line 1262, in wait
    return self._wait(timeout=timeout)
  File "/usr/lib/python3.11/subprocess.py", line 1997, in _wait
    (pid, sts) = self._try_wait(0)
  File "/usr/lib/python3.11/subprocess.py", line 1955, in _try_wait
    (pid, sts) = os.waitpid(self.pid, wait_flags)

[2025-02-16 08:31:13] [WARNING ] discord.gateway: Shard ID None heartbeat blocked for more than 180 seconds.
Loop thread traceback (most recent call last):
  File "/home/lucassukeunkim/scuffed_discord_bot/bot.py", line 682, in <module>
    bot.run(BOT_TOKEN, reconnect=True)
  File "/home/lucassukeunkim/myenv/lib/python3.11/site-packages/discord/client.py", line 869, in run
    asyncio.run(runner())
  File "/usr/lib/python3.11/asyncio/runners.py", line 190, in run
    return runner.run(main)
  File "/usr/lib/python3.11/asyncio/runners.py", line 118, in run
    return self._loop.run_until_complete(task)
  File "/usr/lib/python3.11/asyncio/base_events.py", line 640, in run_until_complete
    self.run_forever()
  File "/usr/lib/python3.11/asyncio/base_events.py", line 607, in run_forever
    self._run_once()
  File "/usr/lib/python3.11/asyncio/base_events.py", line 1922, in _run_once
    handle._run()
  File "/usr/lib/python3.11/asyncio/events.py", line 80, in _run
    self._context.run(self._callback, *self._args)
  File "/home/lucassukeunkim/myenv/lib/python3.11/site-packages/discord/client.py", line 449, in _run_event
    await coro(*args, **kwargs)
  File "/home/lucassukeunkim/scuffed_discord_bot/bot.py", line 48, in on_message
    await bot.process_commands(message)
  File "/home/lucassukeunkim/myenv/lib/python3.11/site-packages/discord/ext/commands/bot.py", line 1408, in process_commands
    await self.invoke(ctx)  # type: ignore
  File "/home/lucassukeunkim/myenv/lib/python3.11/site-packages/discord/ext/commands/bot.py", line 1366, in invoke
    await ctx.command.invoke(ctx)
  File "/home/lucassukeunkim/myenv/lib/python3.11/site-packages/discord/ext/commands/core.py", line 1029, in invoke
    await injected(*ctx.args, **ctx.kwargs)  # type: ignore
  File "/home/lucassukeunkim/myenv/lib/python3.11/site-packages/discord/ext/commands/core.py", line 235, in wrapped
    ret = await coro(*args, **kwargs)
  File "/home/lucassukeunkim/scuffed_discord_bot/bot.py", line 580, in pushtextfiles
    subprocess.run(["git", "fetch"], check=True)
  File "/usr/lib/python3.11/subprocess.py", line 550, in run
    stdout, stderr = process.communicate(input, timeout=timeout)
  File "/usr/lib/python3.11/subprocess.py", line 1199, in communicate
    self.wait()
  File "/usr/lib/python3.11/subprocess.py", line 1262, in wait
    return self._wait(timeout=timeout)
  File "/usr/lib/python3.11/subprocess.py", line 1997, in _wait
    (pid, sts) = self._try_wait(0)
  File "/usr/lib/python3.11/subprocess.py", line 1955, in _try_wait
    (pid, sts) = os.waitpid(self.pid, wait_flags)

[2025-02-16 08:31:23] [WARNING ] discord.gateway: Shard ID None heartbeat blocked for more than 190 seconds.
Loop thread traceback (most recent call last):
  File "/home/lucassukeunkim/scuffed_discord_bot/bot.py", line 682, in <module>
    bot.run(BOT_TOKEN, reconnect=True)
  File "/home/lucassukeunkim/myenv/lib/python3.11/site-packages/discord/client.py", line 869, in run
    asyncio.run(runner())
  File "/usr/lib/python3.11/asyncio/runners.py", line 190, in run
    return runner.run(main)
  File "/usr/lib/python3.11/asyncio/runners.py", line 118, in run
    return self._loop.run_until_complete(task)
  File "/usr/lib/python3.11/asyncio/base_events.py", line 640, in run_until_complete
    self.run_forever()
  File "/usr/lib/python3.11/asyncio/base_events.py", line 607, in run_forever
    self._run_once()
  File "/usr/lib/python3.11/asyncio/base_events.py", line 1922, in _run_once
    handle._run()
  File "/usr/lib/python3.11/asyncio/events.py", line 80, in _run
    self._context.run(self._callback, *self._args)
  File "/home/lucassukeunkim/myenv/lib/python3.11/site-packages/discord/client.py", line 449, in _run_event
    await coro(*args, **kwargs)
  File "/home/lucassukeunkim/scuffed_discord_bot/bot.py", line 48, in on_message
    await bot.process_commands(message)
  File "/home/lucassukeunkim/myenv/lib/python3.11/site-packages/discord/ext/commands/bot.py", line 1408, in process_commands
    await self.invoke(ctx)  # type: ignore
  File "/home/lucassukeunkim/myenv/lib/python3.11/site-packages/discord/ext/commands/bot.py", line 1366, in invoke
    await ctx.command.invoke(ctx)
  File "/home/lucassukeunkim/myenv/lib/python3.11/site-packages/discord/ext/commands/core.py", line 1029, in invoke
    await injected(*ctx.args, **ctx.kwargs)  # type: ignore
  File "/home/lucassukeunkim/myenv/lib/python3.11/site-packages/discord/ext/commands/core.py", line 235, in wrapped
    ret = await coro(*args, **kwargs)
  File "/home/lucassukeunkim/scuffed_discord_bot/bot.py", line 580, in pushtextfiles
    subprocess.run(["git", "fetch"], check=True)
  File "/usr/lib/python3.11/subprocess.py", line 550, in run
    stdout, stderr = process.communicate(input, timeout=timeout)
  File "/usr/lib/python3.11/subprocess.py", line 1199, in communicate
    self.wait()
  File "/usr/lib/python3.11/subprocess.py", line 1262, in wait
    return self._wait(timeout=timeout)
  File "/usr/lib/python3.11/subprocess.py", line 1997, in _wait
    (pid, sts) = self._try_wait(0)
  File "/usr/lib/python3.11/subprocess.py", line 1955, in _try_wait
    (pid, sts) = os.waitpid(self.pid, wait_flags)

[2025-02-16 08:31:33] [WARNING ] discord.gateway: Shard ID None heartbeat blocked for more than 200 seconds.
Loop thread traceback (most recent call last):
  File "/home/lucassukeunkim/scuffed_discord_bot/bot.py", line 682, in <module>
    bot.run(BOT_TOKEN, reconnect=True)
  File "/home/lucassukeunkim/myenv/lib/python3.11/site-packages/discord/client.py", line 869, in run
    asyncio.run(runner())
  File "/usr/lib/python3.11/asyncio/runners.py", line 190, in run
    return runner.run(main)
  File "/usr/lib/python3.11/asyncio/runners.py", line 118, in run
    return self._loop.run_until_complete(task)
  File "/usr/lib/python3.11/asyncio/base_events.py", line 640, in run_until_complete
    self.run_forever()
  File "/usr/lib/python3.11/asyncio/base_events.py", line 607, in run_forever
    self._run_once()
  File "/usr/lib/python3.11/asyncio/base_events.py", line 1922, in _run_once
    handle._run()
  File "/usr/lib/python3.11/asyncio/events.py", line 80, in _run
    self._context.run(self._callback, *self._args)
  File "/home/lucassukeunkim/myenv/lib/python3.11/site-packages/discord/client.py", line 449, in _run_event
    await coro(*args, **kwargs)
  File "/home/lucassukeunkim/scuffed_discord_bot/bot.py", line 48, in on_message
    await bot.process_commands(message)
  File "/home/lucassukeunkim/myenv/lib/python3.11/site-packages/discord/ext/commands/bot.py", line 1408, in process_commands
    await self.invoke(ctx)  # type: ignore
  File "/home/lucassukeunkim/myenv/lib/python3.11/site-packages/discord/ext/commands/bot.py", line 1366, in invoke
    await ctx.command.invoke(ctx)
  File "/home/lucassukeunkim/myenv/lib/python3.11/site-packages/discord/ext/commands/core.py", line 1029, in invoke
    await injected(*ctx.args, **ctx.kwargs)  # type: ignore
  File "/home/lucassukeunkim/myenv/lib/python3.11/site-packages/discord/ext/commands/core.py", line 235, in wrapped
    ret = await coro(*args, **kwargs)
  File "/home/lucassukeunkim/scuffed_discord_bot/bot.py", line 580, in pushtextfiles
    subprocess.run(["git", "fetch"], check=True)
  File "/usr/lib/python3.11/subprocess.py", line 550, in run
    stdout, stderr = process.communicate(input, timeout=timeout)
  File "/usr/lib/python3.11/subprocess.py", line 1199, in communicate
    self.wait()
  File "/usr/lib/python3.11/subprocess.py", line 1262, in wait
    return self._wait(timeout=timeout)
  File "/usr/lib/python3.11/subprocess.py", line 1997, in _wait
    (pid, sts) = self._try_wait(0)
  File "/usr/lib/python3.11/subprocess.py", line 1955, in _try_wait
    (pid, sts) = os.waitpid(self.pid, wait_flags)

[2025-02-16 08:31:43] [WARNING ] discord.gateway: Shard ID None heartbeat blocked for more than 210 seconds.
Loop thread traceback (most recent call last):
  File "/home/lucassukeunkim/scuffed_discord_bot/bot.py", line 682, in <module>
    bot.run(BOT_TOKEN, reconnect=True)
  File "/home/lucassukeunkim/myenv/lib/python3.11/site-packages/discord/client.py", line 869, in run
    asyncio.run(runner())
  File "/usr/lib/python3.11/asyncio/runners.py", line 190, in run
    return runner.run(main)
  File "/usr/lib/python3.11/asyncio/runners.py", line 118, in run
    return self._loop.run_until_complete(task)
  File "/usr/lib/python3.11/asyncio/base_events.py", line 640, in run_until_complete
    self.run_forever()
  File "/usr/lib/python3.11/asyncio/base_events.py", line 607, in run_forever
    self._run_once()
  File "/usr/lib/python3.11/asyncio/base_events.py", line 1922, in _run_once
    handle._run()
  File "/usr/lib/python3.11/asyncio/events.py", line 80, in _run
    self._context.run(self._callback, *self._args)
  File "/home/lucassukeunkim/myenv/lib/python3.11/site-packages/discord/client.py", line 449, in _run_event
    await coro(*args, **kwargs)
  File "/home/lucassukeunkim/scuffed_discord_bot/bot.py", line 48, in on_message
    await bot.process_commands(message)
  File "/home/lucassukeunkim/myenv/lib/python3.11/site-packages/discord/ext/commands/bot.py", line 1408, in process_commands
    await self.invoke(ctx)  # type: ignore
  File "/home/lucassukeunkim/myenv/lib/python3.11/site-packages/discord/ext/commands/bot.py", line 1366, in invoke
    await ctx.command.invoke(ctx)
  File "/home/lucassukeunkim/myenv/lib/python3.11/site-packages/discord/ext/commands/core.py", line 1029, in invoke
    await injected(*ctx.args, **ctx.kwargs)  # type: ignore
  File "/home/lucassukeunkim/myenv/lib/python3.11/site-packages/discord/ext/commands/core.py", line 235, in wrapped
    ret = await coro(*args, **kwargs)
  File "/home/lucassukeunkim/scuffed_discord_bot/bot.py", line 580, in pushtextfiles
    subprocess.run(["git", "fetch"], check=True)
  File "/usr/lib/python3.11/subprocess.py", line 550, in run
    stdout, stderr = process.communicate(input, timeout=timeout)
  File "/usr/lib/python3.11/subprocess.py", line 1199, in communicate
    self.wait()
  File "/usr/lib/python3.11/subprocess.py", line 1262, in wait
    return self._wait(timeout=timeout)
  File "/usr/lib/python3.11/subprocess.py", line 1997, in _wait
    (pid, sts) = self._try_wait(0)
  File "/usr/lib/python3.11/subprocess.py", line 1955, in _try_wait
    (pid, sts) = os.waitpid(self.pid, wait_flags)

[2025-02-16 08:31:53] [WARNING ] discord.gateway: Shard ID None heartbeat blocked for more than 220 seconds.
Loop thread traceback (most recent call last):
  File "/home/lucassukeunkim/scuffed_discord_bot/bot.py", line 682, in <module>
    bot.run(BOT_TOKEN, reconnect=True)
  File "/home/lucassukeunkim/myenv/lib/python3.11/site-packages/discord/client.py", line 869, in run
    asyncio.run(runner())
  File "/usr/lib/python3.11/asyncio/runners.py", line 190, in run
    return runner.run(main)
  File "/usr/lib/python3.11/asyncio/runners.py", line 118, in run
    return self._loop.run_until_complete(task)
  File "/usr/lib/python3.11/asyncio/base_events.py", line 640, in run_until_complete
    self.run_forever()
  File "/usr/lib/python3.11/asyncio/base_events.py", line 607, in run_forever
    self._run_once()
  File "/usr/lib/python3.11/asyncio/base_events.py", line 1922, in _run_once
    handle._run()
  File "/usr/lib/python3.11/asyncio/events.py", line 80, in _run
    self._context.run(self._callback, *self._args)
  File "/home/lucassukeunkim/myenv/lib/python3.11/site-packages/discord/client.py", line 449, in _run_event
    await coro(*args, **kwargs)
  File "/home/lucassukeunkim/scuffed_discord_bot/bot.py", line 48, in on_message
    await bot.process_commands(message)
  File "/home/lucassukeunkim/myenv/lib/python3.11/site-packages/discord/ext/commands/bot.py", line 1408, in process_commands
    await self.invoke(ctx)  # type: ignore
  File "/home/lucassukeunkim/myenv/lib/python3.11/site-packages/discord/ext/commands/bot.py", line 1366, in invoke
    await ctx.command.invoke(ctx)
  File "/home/lucassukeunkim/myenv/lib/python3.11/site-packages/discord/ext/commands/core.py", line 1029, in invoke
    await injected(*ctx.args, **ctx.kwargs)  # type: ignore
  File "/home/lucassukeunkim/myenv/lib/python3.11/site-packages/discord/ext/commands/core.py", line 235, in wrapped
    ret = await coro(*args, **kwargs)
  File "/home/lucassukeunkim/scuffed_discord_bot/bot.py", line 580, in pushtextfiles
    subprocess.run(["git", "fetch"], check=True)
  File "/usr/lib/python3.11/subprocess.py", line 550, in run
    stdout, stderr = process.communicate(input, timeout=timeout)
  File "/usr/lib/python3.11/subprocess.py", line 1199, in communicate
    self.wait()
  File "/usr/lib/python3.11/subprocess.py", line 1262, in wait
    return self._wait(timeout=timeout)
  File "/usr/lib/python3.11/subprocess.py", line 1997, in _wait
    (pid, sts) = self._try_wait(0)
  File "/usr/lib/python3.11/subprocess.py", line 1955, in _try_wait
    (pid, sts) = os.waitpid(self.pid, wait_flags)

[2025-02-16 08:32:03] [WARNING ] discord.gateway: Shard ID None heartbeat blocked for more than 230 seconds.
Loop thread traceback (most recent call last):
  File "/home/lucassukeunkim/scuffed_discord_bot/bot.py", line 682, in <module>
    bot.run(BOT_TOKEN, reconnect=True)
  File "/home/lucassukeunkim/myenv/lib/python3.11/site-packages/discord/client.py", line 869, in run
    asyncio.run(runner())
  File "/usr/lib/python3.11/asyncio/runners.py", line 190, in run
    return runner.run(main)
  File "/usr/lib/python3.11/asyncio/runners.py", line 118, in run
    return self._loop.run_until_complete(task)
  File "/usr/lib/python3.11/asyncio/base_events.py", line 640, in run_until_complete
    self.run_forever()
  File "/usr/lib/python3.11/asyncio/base_events.py", line 607, in run_forever
    self._run_once()
  File "/usr/lib/python3.11/asyncio/base_events.py", line 1922, in _run_once
    handle._run()
  File "/usr/lib/python3.11/asyncio/events.py", line 80, in _run
    self._context.run(self._callback, *self._args)
  File "/home/lucassukeunkim/myenv/lib/python3.11/site-packages/discord/client.py", line 449, in _run_event
    await coro(*args, **kwargs)
  File "/home/lucassukeunkim/scuffed_discord_bot/bot.py", line 48, in on_message
    await bot.process_commands(message)
  File "/home/lucassukeunkim/myenv/lib/python3.11/site-packages/discord/ext/commands/bot.py", line 1408, in process_commands
    await self.invoke(ctx)  # type: ignore
  File "/home/lucassukeunkim/myenv/lib/python3.11/site-packages/discord/ext/commands/bot.py", line 1366, in invoke
    await ctx.command.invoke(ctx)
  File "/home/lucassukeunkim/myenv/lib/python3.11/site-packages/discord/ext/commands/core.py", line 1029, in invoke
    await injected(*ctx.args, **ctx.kwargs)  # type: ignore
  File "/home/lucassukeunkim/myenv/lib/python3.11/site-packages/discord/ext/commands/core.py", line 235, in wrapped
    ret = await coro(*args, **kwargs)
  File "/home/lucassukeunkim/scuffed_discord_bot/bot.py", line 580, in pushtextfiles
    subprocess.run(["git", "fetch"], check=True)
  File "/usr/lib/python3.11/subprocess.py", line 550, in run
    stdout, stderr = process.communicate(input, timeout=timeout)
  File "/usr/lib/python3.11/subprocess.py", line 1199, in communicate
    self.wait()
  File "/usr/lib/python3.11/subprocess.py", line 1262, in wait
    return self._wait(timeout=timeout)
  File "/usr/lib/python3.11/subprocess.py", line 1997, in _wait
    (pid, sts) = self._try_wait(0)
  File "/usr/lib/python3.11/subprocess.py", line 1955, in _try_wait
    (pid, sts) = os.waitpid(self.pid, wait_flags)

[2025-02-16 08:32:13] [WARNING ] discord.gateway: Shard ID None heartbeat blocked for more than 240 seconds.
Loop thread traceback (most recent call last):
  File "/home/lucassukeunkim/scuffed_discord_bot/bot.py", line 682, in <module>
    bot.run(BOT_TOKEN, reconnect=True)
  File "/home/lucassukeunkim/myenv/lib/python3.11/site-packages/discord/client.py", line 869, in run
    asyncio.run(runner())
  File "/usr/lib/python3.11/asyncio/runners.py", line 190, in run
    return runner.run(main)
  File "/usr/lib/python3.11/asyncio/runners.py", line 118, in run
    return self._loop.run_until_complete(task)
  File "/usr/lib/python3.11/asyncio/base_events.py", line 640, in run_until_complete
    self.run_forever()
  File "/usr/lib/python3.11/asyncio/base_events.py", line 607, in run_forever
    self._run_once()
  File "/usr/lib/python3.11/asyncio/base_events.py", line 1922, in _run_once
    handle._run()
  File "/usr/lib/python3.11/asyncio/events.py", line 80, in _run
    self._context.run(self._callback, *self._args)
  File "/home/lucassukeunkim/myenv/lib/python3.11/site-packages/discord/client.py", line 449, in _run_event
    await coro(*args, **kwargs)
  File "/home/lucassukeunkim/scuffed_discord_bot/bot.py", line 48, in on_message
    await bot.process_commands(message)
  File "/home/lucassukeunkim/myenv/lib/python3.11/site-packages/discord/ext/commands/bot.py", line 1408, in process_commands
    await self.invoke(ctx)  # type: ignore
  File "/home/lucassukeunkim/myenv/lib/python3.11/site-packages/discord/ext/commands/bot.py", line 1366, in invoke
    await ctx.command.invoke(ctx)
  File "/home/lucassukeunkim/myenv/lib/python3.11/site-packages/discord/ext/commands/core.py", line 1029, in invoke
    await injected(*ctx.args, **ctx.kwargs)  # type: ignore
  File "/home/lucassukeunkim/myenv/lib/python3.11/site-packages/discord/ext/commands/core.py", line 235, in wrapped
    ret = await coro(*args, **kwargs)
  File "/home/lucassukeunkim/scuffed_discord_bot/bot.py", line 580, in pushtextfiles
    subprocess.run(["git", "fetch"], check=True)
  File "/usr/lib/python3.11/subprocess.py", line 550, in run
    stdout, stderr = process.communicate(input, timeout=timeout)
  File "/usr/lib/python3.11/subprocess.py", line 1199, in communicate
    self.wait()
  File "/usr/lib/python3.11/subprocess.py", line 1262, in wait
    return self._wait(timeout=timeout)
  File "/usr/lib/python3.11/subprocess.py", line 1997, in _wait
    (pid, sts) = self._try_wait(0)
  File "/usr/lib/python3.11/subprocess.py", line 1955, in _try_wait
    (pid, sts) = os.waitpid(self.pid, wait_flags)

[2025-02-16 08:32:23] [WARNING ] discord.gateway: Shard ID None heartbeat blocked for more than 250 seconds.
Loop thread traceback (most recent call last):
  File "/home/lucassukeunkim/scuffed_discord_bot/bot.py", line 682, in <module>
    bot.run(BOT_TOKEN, reconnect=True)
  File "/home/lucassukeunkim/myenv/lib/python3.11/site-packages/discord/client.py", line 869, in run
    asyncio.run(runner())
  File "/usr/lib/python3.11/asyncio/runners.py", line 190, in run
    return runner.run(main)
  File "/usr/lib/python3.11/asyncio/runners.py", line 118, in run
    return self._loop.run_until_complete(task)
  File "/usr/lib/python3.11/asyncio/base_events.py", line 640, in run_until_complete
    self.run_forever()
  File "/usr/lib/python3.11/asyncio/base_events.py", line 607, in run_forever
    self._run_once()
  File "/usr/lib/python3.11/asyncio/base_events.py", line 1922, in _run_once
    handle._run()
  File "/usr/lib/python3.11/asyncio/events.py", line 80, in _run
    self._context.run(self._callback, *self._args)
  File "/home/lucassukeunkim/myenv/lib/python3.11/site-packages/discord/client.py", line 449, in _run_event
    await coro(*args, **kwargs)
  File "/home/lucassukeunkim/scuffed_discord_bot/bot.py", line 48, in on_message
    await bot.process_commands(message)
  File "/home/lucassukeunkim/myenv/lib/python3.11/site-packages/discord/ext/commands/bot.py", line 1408, in process_commands
    await self.invoke(ctx)  # type: ignore
  File "/home/lucassukeunkim/myenv/lib/python3.11/site-packages/discord/ext/commands/bot.py", line 1366, in invoke
    await ctx.command.invoke(ctx)
  File "/home/lucassukeunkim/myenv/lib/python3.11/site-packages/discord/ext/commands/core.py", line 1029, in invoke
    await injected(*ctx.args, **ctx.kwargs)  # type: ignore
  File "/home/lucassukeunkim/myenv/lib/python3.11/site-packages/discord/ext/commands/core.py", line 235, in wrapped
    ret = await coro(*args, **kwargs)
  File "/home/lucassukeunkim/scuffed_discord_bot/bot.py", line 580, in pushtextfiles
    subprocess.run(["git", "fetch"], check=True)
  File "/usr/lib/python3.11/subprocess.py", line 550, in run
    stdout, stderr = process.communicate(input, timeout=timeout)
  File "/usr/lib/python3.11/subprocess.py", line 1199, in communicate
    self.wait()
  File "/usr/lib/python3.11/subprocess.py", line 1262, in wait
    return self._wait(timeout=timeout)
  File "/usr/lib/python3.11/subprocess.py", line 1997, in _wait
    (pid, sts) = self._try_wait(0)
  File "/usr/lib/python3.11/subprocess.py", line 1955, in _try_wait
    (pid, sts) = os.waitpid(self.pid, wait_flags)

[2025-02-16 08:32:33] [WARNING ] discord.gateway: Shard ID None heartbeat blocked for more than 260 seconds.
Loop thread traceback (most recent call last):
  File "/home/lucassukeunkim/scuffed_discord_bot/bot.py", line 682, in <module>
    bot.run(BOT_TOKEN, reconnect=True)
  File "/home/lucassukeunkim/myenv/lib/python3.11/site-packages/discord/client.py", line 869, in run
    asyncio.run(runner())
  File "/usr/lib/python3.11/asyncio/runners.py", line 190, in run
    return runner.run(main)
  File "/usr/lib/python3.11/asyncio/runners.py", line 118, in run
    return self._loop.run_until_complete(task)
  File "/usr/lib/python3.11/asyncio/base_events.py", line 640, in run_until_complete
    self.run_forever()
  File "/usr/lib/python3.11/asyncio/base_events.py", line 607, in run_forever
    self._run_once()
  File "/usr/lib/python3.11/asyncio/base_events.py", line 1922, in _run_once
    handle._run()
  File "/usr/lib/python3.11/asyncio/events.py", line 80, in _run
    self._context.run(self._callback, *self._args)
  File "/home/lucassukeunkim/myenv/lib/python3.11/site-packages/discord/client.py", line 449, in _run_event
    await coro(*args, **kwargs)
  File "/home/lucassukeunkim/scuffed_discord_bot/bot.py", line 48, in on_message
    await bot.process_commands(message)
  File "/home/lucassukeunkim/myenv/lib/python3.11/site-packages/discord/ext/commands/bot.py", line 1408, in process_commands
    await self.invoke(ctx)  # type: ignore
  File "/home/lucassukeunkim/myenv/lib/python3.11/site-packages/discord/ext/commands/bot.py", line 1366, in invoke
    await ctx.command.invoke(ctx)
  File "/home/lucassukeunkim/myenv/lib/python3.11/site-packages/discord/ext/commands/core.py", line 1029, in invoke
    await injected(*ctx.args, **ctx.kwargs)  # type: ignore
  File "/home/lucassukeunkim/myenv/lib/python3.11/site-packages/discord/ext/commands/core.py", line 235, in wrapped
    ret = await coro(*args, **kwargs)
  File "/home/lucassukeunkim/scuffed_discord_bot/bot.py", line 580, in pushtextfiles
    subprocess.run(["git", "fetch"], check=True)
  File "/usr/lib/python3.11/subprocess.py", line 550, in run
    stdout, stderr = process.communicate(input, timeout=timeout)
  File "/usr/lib/python3.11/subprocess.py", line 1199, in communicate
    self.wait()
  File "/usr/lib/python3.11/subprocess.py", line 1262, in wait
    return self._wait(timeout=timeout)
  File "/usr/lib/python3.11/subprocess.py", line 1997, in _wait
    (pid, sts) = self._try_wait(0)
  File "/usr/lib/python3.11/subprocess.py", line 1955, in _try_wait
    (pid, sts) = os.waitpid(self.pid, wait_flags)

[2025-02-16 08:32:43] [WARNING ] discord.gateway: Shard ID None heartbeat blocked for more than 270 seconds.
Loop thread traceback (most recent call last):
  File "/home/lucassukeunkim/scuffed_discord_bot/bot.py", line 682, in <module>
    bot.run(BOT_TOKEN, reconnect=True)
  File "/home/lucassukeunkim/myenv/lib/python3.11/site-packages/discord/client.py", line 869, in run
    asyncio.run(runner())
  File "/usr/lib/python3.11/asyncio/runners.py", line 190, in run
    return runner.run(main)
  File "/usr/lib/python3.11/asyncio/runners.py", line 118, in run
    return self._loop.run_until_complete(task)
  File "/usr/lib/python3.11/asyncio/base_events.py", line 640, in run_until_complete
    self.run_forever()
  File "/usr/lib/python3.11/asyncio/base_events.py", line 607, in run_forever
    self._run_once()
  File "/usr/lib/python3.11/asyncio/base_events.py", line 1922, in _run_once
    handle._run()
  File "/usr/lib/python3.11/asyncio/events.py", line 80, in _run
    self._context.run(self._callback, *self._args)
  File "/home/lucassukeunkim/myenv/lib/python3.11/site-packages/discord/client.py", line 449, in _run_event
    await coro(*args, **kwargs)
  File "/home/lucassukeunkim/scuffed_discord_bot/bot.py", line 48, in on_message
    await bot.process_commands(message)
  File "/home/lucassukeunkim/myenv/lib/python3.11/site-packages/discord/ext/commands/bot.py", line 1408, in process_commands
    await self.invoke(ctx)  # type: ignore
  File "/home/lucassukeunkim/myenv/lib/python3.11/site-packages/discord/ext/commands/bot.py", line 1366, in invoke
    await ctx.command.invoke(ctx)
  File "/home/lucassukeunkim/myenv/lib/python3.11/site-packages/discord/ext/commands/core.py", line 1029, in invoke
    await injected(*ctx.args, **ctx.kwargs)  # type: ignore
  File "/home/lucassukeunkim/myenv/lib/python3.11/site-packages/discord/ext/commands/core.py", line 235, in wrapped
    ret = await coro(*args, **kwargs)
  File "/home/lucassukeunkim/scuffed_discord_bot/bot.py", line 580, in pushtextfiles
    subprocess.run(["git", "fetch"], check=True)
  File "/usr/lib/python3.11/subprocess.py", line 550, in run
    stdout, stderr = process.communicate(input, timeout=timeout)
  File "/usr/lib/python3.11/subprocess.py", line 1199, in communicate
    self.wait()
  File "/usr/lib/python3.11/subprocess.py", line 1262, in wait
    return self._wait(timeout=timeout)
  File "/usr/lib/python3.11/subprocess.py", line 1997, in _wait
    (pid, sts) = self._try_wait(0)
  File "/usr/lib/python3.11/subprocess.py", line 1955, in _try_wait
    (pid, sts) = os.waitpid(self.pid, wait_flags)

[2025-02-16 08:32:53] [WARNING ] discord.gateway: Shard ID None heartbeat blocked for more than 280 seconds.
Loop thread traceback (most recent call last):
  File "/home/lucassukeunkim/scuffed_discord_bot/bot.py", line 682, in <module>
    bot.run(BOT_TOKEN, reconnect=True)
  File "/home/lucassukeunkim/myenv/lib/python3.11/site-packages/discord/client.py", line 869, in run
    asyncio.run(runner())
  File "/usr/lib/python3.11/asyncio/runners.py", line 190, in run
    return runner.run(main)
  File "/usr/lib/python3.11/asyncio/runners.py", line 118, in run
    return self._loop.run_until_complete(task)
  File "/usr/lib/python3.11/asyncio/base_events.py", line 640, in run_until_complete
    self.run_forever()
  File "/usr/lib/python3.11/asyncio/base_events.py", line 607, in run_forever
    self._run_once()
  File "/usr/lib/python3.11/asyncio/base_events.py", line 1922, in _run_once
    handle._run()
  File "/usr/lib/python3.11/asyncio/events.py", line 80, in _run
    self._context.run(self._callback, *self._args)
  File "/home/lucassukeunkim/myenv/lib/python3.11/site-packages/discord/client.py", line 449, in _run_event
    await coro(*args, **kwargs)
  File "/home/lucassukeunkim/scuffed_discord_bot/bot.py", line 48, in on_message
    await bot.process_commands(message)
  File "/home/lucassukeunkim/myenv/lib/python3.11/site-packages/discord/ext/commands/bot.py", line 1408, in process_commands
    await self.invoke(ctx)  # type: ignore
  File "/home/lucassukeunkim/myenv/lib/python3.11/site-packages/discord/ext/commands/bot.py", line 1366, in invoke
    await ctx.command.invoke(ctx)
  File "/home/lucassukeunkim/myenv/lib/python3.11/site-packages/discord/ext/commands/core.py", line 1029, in invoke
    await injected(*ctx.args, **ctx.kwargs)  # type: ignore
  File "/home/lucassukeunkim/myenv/lib/python3.11/site-packages/discord/ext/commands/core.py", line 235, in wrapped
    ret = await coro(*args, **kwargs)
  File "/home/lucassukeunkim/scuffed_discord_bot/bot.py", line 580, in pushtextfiles
    subprocess.run(["git", "fetch"], check=True)
  File "/usr/lib/python3.11/subprocess.py", line 550, in run
    stdout, stderr = process.communicate(input, timeout=timeout)
  File "/usr/lib/python3.11/subprocess.py", line 1199, in communicate
    self.wait()
  File "/usr/lib/python3.11/subprocess.py", line 1262, in wait
    return self._wait(timeout=timeout)
  File "/usr/lib/python3.11/subprocess.py", line 1997, in _wait
    (pid, sts) = self._try_wait(0)
  File "/usr/lib/python3.11/subprocess.py", line 1955, in _try_wait
    (pid, sts) = os.waitpid(self.pid, wait_flags)

[2025-02-16 08:33:03] [WARNING ] discord.gateway: Shard ID None heartbeat blocked for more than 290 seconds.
Loop thread traceback (most recent call last):
  File "/home/lucassukeunkim/scuffed_discord_bot/bot.py", line 682, in <module>
    bot.run(BOT_TOKEN, reconnect=True)
  File "/home/lucassukeunkim/myenv/lib/python3.11/site-packages/discord/client.py", line 869, in run
    asyncio.run(runner())
  File "/usr/lib/python3.11/asyncio/runners.py", line 190, in run
    return runner.run(main)
  File "/usr/lib/python3.11/asyncio/runners.py", line 118, in run
    return self._loop.run_until_complete(task)
  File "/usr/lib/python3.11/asyncio/base_events.py", line 640, in run_until_complete
    self.run_forever()
  File "/usr/lib/python3.11/asyncio/base_events.py", line 607, in run_forever
    self._run_once()
  File "/usr/lib/python3.11/asyncio/base_events.py", line 1922, in _run_once
    handle._run()
  File "/usr/lib/python3.11/asyncio/events.py", line 80, in _run
    self._context.run(self._callback, *self._args)
  File "/home/lucassukeunkim/myenv/lib/python3.11/site-packages/discord/client.py", line 449, in _run_event
    await coro(*args, **kwargs)
  File "/home/lucassukeunkim/scuffed_discord_bot/bot.py", line 48, in on_message
    await bot.process_commands(message)
  File "/home/lucassukeunkim/myenv/lib/python3.11/site-packages/discord/ext/commands/bot.py", line 1408, in process_commands
    await self.invoke(ctx)  # type: ignore
  File "/home/lucassukeunkim/myenv/lib/python3.11/site-packages/discord/ext/commands/bot.py", line 1366, in invoke
    await ctx.command.invoke(ctx)
  File "/home/lucassukeunkim/myenv/lib/python3.11/site-packages/discord/ext/commands/core.py", line 1029, in invoke
    await injected(*ctx.args, **ctx.kwargs)  # type: ignore
  File "/home/lucassukeunkim/myenv/lib/python3.11/site-packages/discord/ext/commands/core.py", line 235, in wrapped
    ret = await coro(*args, **kwargs)
  File "/home/lucassukeunkim/scuffed_discord_bot/bot.py", line 580, in pushtextfiles
    subprocess.run(["git", "fetch"], check=True)
  File "/usr/lib/python3.11/subprocess.py", line 550, in run
    stdout, stderr = process.communicate(input, timeout=timeout)
  File "/usr/lib/python3.11/subprocess.py", line 1199, in communicate
    self.wait()
  File "/usr/lib/python3.11/subprocess.py", line 1262, in wait
    return self._wait(timeout=timeout)
  File "/usr/lib/python3.11/subprocess.py", line 1997, in _wait
    (pid, sts) = self._try_wait(0)
  File "/usr/lib/python3.11/subprocess.py", line 1955, in _try_wait
    (pid, sts) = os.waitpid(self.pid, wait_flags)

[2025-02-16 08:33:13] [WARNING ] discord.gateway: Shard ID None heartbeat blocked for more than 300 seconds.
Loop thread traceback (most recent call last):
  File "/home/lucassukeunkim/scuffed_discord_bot/bot.py", line 682, in <module>
    bot.run(BOT_TOKEN, reconnect=True)
  File "/home/lucassukeunkim/myenv/lib/python3.11/site-packages/discord/client.py", line 869, in run
    asyncio.run(runner())
  File "/usr/lib/python3.11/asyncio/runners.py", line 190, in run
    return runner.run(main)
  File "/usr/lib/python3.11/asyncio/runners.py", line 118, in run
    return self._loop.run_until_complete(task)
  File "/usr/lib/python3.11/asyncio/base_events.py", line 640, in run_until_complete
    self.run_forever()
  File "/usr/lib/python3.11/asyncio/base_events.py", line 607, in run_forever
    self._run_once()
  File "/usr/lib/python3.11/asyncio/base_events.py", line 1922, in _run_once
    handle._run()
  File "/usr/lib/python3.11/asyncio/events.py", line 80, in _run
    self._context.run(self._callback, *self._args)
  File "/home/lucassukeunkim/myenv/lib/python3.11/site-packages/discord/client.py", line 449, in _run_event
    await coro(*args, **kwargs)
  File "/home/lucassukeunkim/scuffed_discord_bot/bot.py", line 48, in on_message
    await bot.process_commands(message)
  File "/home/lucassukeunkim/myenv/lib/python3.11/site-packages/discord/ext/commands/bot.py", line 1408, in process_commands
    await self.invoke(ctx)  # type: ignore
  File "/home/lucassukeunkim/myenv/lib/python3.11/site-packages/discord/ext/commands/bot.py", line 1366, in invoke
    await ctx.command.invoke(ctx)
  File "/home/lucassukeunkim/myenv/lib/python3.11/site-packages/discord/ext/commands/core.py", line 1029, in invoke
    await injected(*ctx.args, **ctx.kwargs)  # type: ignore
  File "/home/lucassukeunkim/myenv/lib/python3.11/site-packages/discord/ext/commands/core.py", line 235, in wrapped
    ret = await coro(*args, **kwargs)
  File "/home/lucassukeunkim/scuffed_discord_bot/bot.py", line 580, in pushtextfiles
    subprocess.run(["git", "fetch"], check=True)
  File "/usr/lib/python3.11/subprocess.py", line 550, in run
    stdout, stderr = process.communicate(input, timeout=timeout)
  File "/usr/lib/python3.11/subprocess.py", line 1199, in communicate
    self.wait()
  File "/usr/lib/python3.11/subprocess.py", line 1262, in wait
    return self._wait(timeout=timeout)
  File "/usr/lib/python3.11/subprocess.py", line 1997, in _wait
    (pid, sts) = self._try_wait(0)
  File "/usr/lib/python3.11/subprocess.py", line 1955, in _try_wait
    (pid, sts) = os.waitpid(self.pid, wait_flags)

[2025-02-16 08:33:23] [WARNING ] discord.gateway: Shard ID None heartbeat blocked for more than 310 seconds.
Loop thread traceback (most recent call last):
  File "/home/lucassukeunkim/scuffed_discord_bot/bot.py", line 682, in <module>
    bot.run(BOT_TOKEN, reconnect=True)
  File "/home/lucassukeunkim/myenv/lib/python3.11/site-packages/discord/client.py", line 869, in run
    asyncio.run(runner())
  File "/usr/lib/python3.11/asyncio/runners.py", line 190, in run
    return runner.run(main)
  File "/usr/lib/python3.11/asyncio/runners.py", line 118, in run
    return self._loop.run_until_complete(task)
  File "/usr/lib/python3.11/asyncio/base_events.py", line 640, in run_until_complete
    self.run_forever()
  File "/usr/lib/python3.11/asyncio/base_events.py", line 607, in run_forever
    self._run_once()
  File "/usr/lib/python3.11/asyncio/base_events.py", line 1922, in _run_once
    handle._run()
  File "/usr/lib/python3.11/asyncio/events.py", line 80, in _run
    self._context.run(self._callback, *self._args)
  File "/home/lucassukeunkim/myenv/lib/python3.11/site-packages/discord/client.py", line 449, in _run_event
    await coro(*args, **kwargs)
  File "/home/lucassukeunkim/scuffed_discord_bot/bot.py", line 48, in on_message
    await bot.process_commands(message)
  File "/home/lucassukeunkim/myenv/lib/python3.11/site-packages/discord/ext/commands/bot.py", line 1408, in process_commands
    await self.invoke(ctx)  # type: ignore
  File "/home/lucassukeunkim/myenv/lib/python3.11/site-packages/discord/ext/commands/bot.py", line 1366, in invoke
    await ctx.command.invoke(ctx)
  File "/home/lucassukeunkim/myenv/lib/python3.11/site-packages/discord/ext/commands/core.py", line 1029, in invoke
    await injected(*ctx.args, **ctx.kwargs)  # type: ignore
  File "/home/lucassukeunkim/myenv/lib/python3.11/site-packages/discord/ext/commands/core.py", line 235, in wrapped
    ret = await coro(*args, **kwargs)
  File "/home/lucassukeunkim/scuffed_discord_bot/bot.py", line 580, in pushtextfiles
    subprocess.run(["git", "fetch"], check=True)
  File "/usr/lib/python3.11/subprocess.py", line 550, in run
    stdout, stderr = process.communicate(input, timeout=timeout)
  File "/usr/lib/python3.11/subprocess.py", line 1199, in communicate
    self.wait()
  File "/usr/lib/python3.11/subprocess.py", line 1262, in wait
    return self._wait(timeout=timeout)
  File "/usr/lib/python3.11/subprocess.py", line 1997, in _wait
    (pid, sts) = self._try_wait(0)
  File "/usr/lib/python3.11/subprocess.py", line 1955, in _try_wait
    (pid, sts) = os.waitpid(self.pid, wait_flags)

[2025-02-16 08:33:33] [WARNING ] discord.gateway: Shard ID None heartbeat blocked for more than 320 seconds.
Loop thread traceback (most recent call last):
  File "/home/lucassukeunkim/scuffed_discord_bot/bot.py", line 682, in <module>
    bot.run(BOT_TOKEN, reconnect=True)
  File "/home/lucassukeunkim/myenv/lib/python3.11/site-packages/discord/client.py", line 869, in run
    asyncio.run(runner())
  File "/usr/lib/python3.11/asyncio/runners.py", line 190, in run
    return runner.run(main)
  File "/usr/lib/python3.11/asyncio/runners.py", line 118, in run
    return self._loop.run_until_complete(task)
  File "/usr/lib/python3.11/asyncio/base_events.py", line 640, in run_until_complete
    self.run_forever()
  File "/usr/lib/python3.11/asyncio/base_events.py", line 607, in run_forever
    self._run_once()
  File "/usr/lib/python3.11/asyncio/base_events.py", line 1922, in _run_once
    handle._run()
  File "/usr/lib/python3.11/asyncio/events.py", line 80, in _run
    self._context.run(self._callback, *self._args)
  File "/home/lucassukeunkim/myenv/lib/python3.11/site-packages/discord/client.py", line 449, in _run_event
    await coro(*args, **kwargs)
  File "/home/lucassukeunkim/scuffed_discord_bot/bot.py", line 48, in on_message
    await bot.process_commands(message)
  File "/home/lucassukeunkim/myenv/lib/python3.11/site-packages/discord/ext/commands/bot.py", line 1408, in process_commands
    await self.invoke(ctx)  # type: ignore
  File "/home/lucassukeunkim/myenv/lib/python3.11/site-packages/discord/ext/commands/bot.py", line 1366, in invoke
    await ctx.command.invoke(ctx)
  File "/home/lucassukeunkim/myenv/lib/python3.11/site-packages/discord/ext/commands/core.py", line 1029, in invoke
    await injected(*ctx.args, **ctx.kwargs)  # type: ignore
  File "/home/lucassukeunkim/myenv/lib/python3.11/site-packages/discord/ext/commands/core.py", line 235, in wrapped
    ret = await coro(*args, **kwargs)
  File "/home/lucassukeunkim/scuffed_discord_bot/bot.py", line 580, in pushtextfiles
    subprocess.run(["git", "fetch"], check=True)
  File "/usr/lib/python3.11/subprocess.py", line 550, in run
    stdout, stderr = process.communicate(input, timeout=timeout)
  File "/usr/lib/python3.11/subprocess.py", line 1199, in communicate
    self.wait()
  File "/usr/lib/python3.11/subprocess.py", line 1262, in wait
    return self._wait(timeout=timeout)
  File "/usr/lib/python3.11/subprocess.py", line 1997, in _wait
    (pid, sts) = self._try_wait(0)
  File "/usr/lib/python3.11/subprocess.py", line 1955, in _try_wait
    (pid, sts) = os.waitpid(self.pid, wait_flags)

[2025-02-16 08:33:43] [WARNING ] discord.gateway: Shard ID None heartbeat blocked for more than 330 seconds.
Loop thread traceback (most recent call last):
  File "/home/lucassukeunkim/scuffed_discord_bot/bot.py", line 682, in <module>
    bot.run(BOT_TOKEN, reconnect=True)
  File "/home/lucassukeunkim/myenv/lib/python3.11/site-packages/discord/client.py", line 869, in run
    asyncio.run(runner())
  File "/usr/lib/python3.11/asyncio/runners.py", line 190, in run
    return runner.run(main)
  File "/usr/lib/python3.11/asyncio/runners.py", line 118, in run
    return self._loop.run_until_complete(task)
  File "/usr/lib/python3.11/asyncio/base_events.py", line 640, in run_until_complete
    self.run_forever()
  File "/usr/lib/python3.11/asyncio/base_events.py", line 607, in run_forever
    self._run_once()
  File "/usr/lib/python3.11/asyncio/base_events.py", line 1922, in _run_once
    handle._run()
  File "/usr/lib/python3.11/asyncio/events.py", line 80, in _run
    self._context.run(self._callback, *self._args)
  File "/home/lucassukeunkim/myenv/lib/python3.11/site-packages/discord/client.py", line 449, in _run_event
    await coro(*args, **kwargs)
  File "/home/lucassukeunkim/scuffed_discord_bot/bot.py", line 48, in on_message
    await bot.process_commands(message)
  File "/home/lucassukeunkim/myenv/lib/python3.11/site-packages/discord/ext/commands/bot.py", line 1408, in process_commands
    await self.invoke(ctx)  # type: ignore
  File "/home/lucassukeunkim/myenv/lib/python3.11/site-packages/discord/ext/commands/bot.py", line 1366, in invoke
    await ctx.command.invoke(ctx)
  File "/home/lucassukeunkim/myenv/lib/python3.11/site-packages/discord/ext/commands/core.py", line 1029, in invoke
    await injected(*ctx.args, **ctx.kwargs)  # type: ignore
  File "/home/lucassukeunkim/myenv/lib/python3.11/site-packages/discord/ext/commands/core.py", line 235, in wrapped
    ret = await coro(*args, **kwargs)
  File "/home/lucassukeunkim/scuffed_discord_bot/bot.py", line 580, in pushtextfiles
    subprocess.run(["git", "fetch"], check=True)
  File "/usr/lib/python3.11/subprocess.py", line 550, in run
    stdout, stderr = process.communicate(input, timeout=timeout)
  File "/usr/lib/python3.11/subprocess.py", line 1199, in communicate
    self.wait()
  File "/usr/lib/python3.11/subprocess.py", line 1262, in wait
    return self._wait(timeout=timeout)
  File "/usr/lib/python3.11/subprocess.py", line 1997, in _wait
    (pid, sts) = self._try_wait(0)
  File "/usr/lib/python3.11/subprocess.py", line 1955, in _try_wait
    (pid, sts) = os.waitpid(self.pid, wait_flags)

[2025-02-16 08:33:53] [WARNING ] discord.gateway: Shard ID None heartbeat blocked for more than 340 seconds.
Loop thread traceback (most recent call last):
  File "/home/lucassukeunkim/scuffed_discord_bot/bot.py", line 682, in <module>
    bot.run(BOT_TOKEN, reconnect=True)
  File "/home/lucassukeunkim/myenv/lib/python3.11/site-packages/discord/client.py", line 869, in run
    asyncio.run(runner())
  File "/usr/lib/python3.11/asyncio/runners.py", line 190, in run
    return runner.run(main)
  File "/usr/lib/python3.11/asyncio/runners.py", line 118, in run
    return self._loop.run_until_complete(task)
  File "/usr/lib/python3.11/asyncio/base_events.py", line 640, in run_until_complete
    self.run_forever()
  File "/usr/lib/python3.11/asyncio/base_events.py", line 607, in run_forever
    self._run_once()
  File "/usr/lib/python3.11/asyncio/base_events.py", line 1922, in _run_once
    handle._run()
  File "/usr/lib/python3.11/asyncio/events.py", line 80, in _run
    self._context.run(self._callback, *self._args)
  File "/home/lucassukeunkim/myenv/lib/python3.11/site-packages/discord/client.py", line 449, in _run_event
    await coro(*args, **kwargs)
  File "/home/lucassukeunkim/scuffed_discord_bot/bot.py", line 48, in on_message
    await bot.process_commands(message)
  File "/home/lucassukeunkim/myenv/lib/python3.11/site-packages/discord/ext/commands/bot.py", line 1408, in process_commands
    await self.invoke(ctx)  # type: ignore
  File "/home/lucassukeunkim/myenv/lib/python3.11/site-packages/discord/ext/commands/bot.py", line 1366, in invoke
    await ctx.command.invoke(ctx)
  File "/home/lucassukeunkim/myenv/lib/python3.11/site-packages/discord/ext/commands/core.py", line 1029, in invoke
    await injected(*ctx.args, **ctx.kwargs)  # type: ignore
  File "/home/lucassukeunkim/myenv/lib/python3.11/site-packages/discord/ext/commands/core.py", line 235, in wrapped
    ret = await coro(*args, **kwargs)
  File "/home/lucassukeunkim/scuffed_discord_bot/bot.py", line 580, in pushtextfiles
    subprocess.run(["git", "fetch"], check=True)
  File "/usr/lib/python3.11/subprocess.py", line 550, in run
    stdout, stderr = process.communicate(input, timeout=timeout)
  File "/usr/lib/python3.11/subprocess.py", line 1199, in communicate
    self.wait()
  File "/usr/lib/python3.11/subprocess.py", line 1262, in wait
    return self._wait(timeout=timeout)
  File "/usr/lib/python3.11/subprocess.py", line 1997, in _wait
    (pid, sts) = self._try_wait(0)
  File "/usr/lib/python3.11/subprocess.py", line 1955, in _try_wait
    (pid, sts) = os.waitpid(self.pid, wait_flags)

[2025-02-16 08:34:03] [WARNING ] discord.gateway: Shard ID None heartbeat blocked for more than 350 seconds.
Loop thread traceback (most recent call last):
  File "/home/lucassukeunkim/scuffed_discord_bot/bot.py", line 682, in <module>
    bot.run(BOT_TOKEN, reconnect=True)
  File "/home/lucassukeunkim/myenv/lib/python3.11/site-packages/discord/client.py", line 869, in run
    asyncio.run(runner())
  File "/usr/lib/python3.11/asyncio/runners.py", line 190, in run
    return runner.run(main)
  File "/usr/lib/python3.11/asyncio/runners.py", line 118, in run
    return self._loop.run_until_complete(task)
  File "/usr/lib/python3.11/asyncio/base_events.py", line 640, in run_until_complete
    self.run_forever()
  File "/usr/lib/python3.11/asyncio/base_events.py", line 607, in run_forever
    self._run_once()
  File "/usr/lib/python3.11/asyncio/base_events.py", line 1922, in _run_once
    handle._run()
  File "/usr/lib/python3.11/asyncio/events.py", line 80, in _run
    self._context.run(self._callback, *self._args)
  File "/home/lucassukeunkim/myenv/lib/python3.11/site-packages/discord/client.py", line 449, in _run_event
    await coro(*args, **kwargs)
  File "/home/lucassukeunkim/scuffed_discord_bot/bot.py", line 48, in on_message
    await bot.process_commands(message)
  File "/home/lucassukeunkim/myenv/lib/python3.11/site-packages/discord/ext/commands/bot.py", line 1408, in process_commands
    await self.invoke(ctx)  # type: ignore
  File "/home/lucassukeunkim/myenv/lib/python3.11/site-packages/discord/ext/commands/bot.py", line 1366, in invoke
    await ctx.command.invoke(ctx)
  File "/home/lucassukeunkim/myenv/lib/python3.11/site-packages/discord/ext/commands/core.py", line 1029, in invoke
    await injected(*ctx.args, **ctx.kwargs)  # type: ignore
  File "/home/lucassukeunkim/myenv/lib/python3.11/site-packages/discord/ext/commands/core.py", line 235, in wrapped
    ret = await coro(*args, **kwargs)
  File "/home/lucassukeunkim/scuffed_discord_bot/bot.py", line 580, in pushtextfiles
    subprocess.run(["git", "fetch"], check=True)
  File "/usr/lib/python3.11/subprocess.py", line 550, in run
    stdout, stderr = process.communicate(input, timeout=timeout)
  File "/usr/lib/python3.11/subprocess.py", line 1199, in communicate
    self.wait()
  File "/usr/lib/python3.11/subprocess.py", line 1262, in wait
    return self._wait(timeout=timeout)
  File "/usr/lib/python3.11/subprocess.py", line 1997, in _wait
    (pid, sts) = self._try_wait(0)
  File "/usr/lib/python3.11/subprocess.py", line 1955, in _try_wait
    (pid, sts) = os.waitpid(self.pid, wait_flags)

[2025-02-16 08:34:13] [WARNING ] discord.gateway: Shard ID None heartbeat blocked for more than 360 seconds.
Loop thread traceback (most recent call last):
  File "/home/lucassukeunkim/scuffed_discord_bot/bot.py", line 682, in <module>
    bot.run(BOT_TOKEN, reconnect=True)
  File "/home/lucassukeunkim/myenv/lib/python3.11/site-packages/discord/client.py", line 869, in run
    asyncio.run(runner())
  File "/usr/lib/python3.11/asyncio/runners.py", line 190, in run
    return runner.run(main)
  File "/usr/lib/python3.11/asyncio/runners.py", line 118, in run
    return self._loop.run_until_complete(task)
  File "/usr/lib/python3.11/asyncio/base_events.py", line 640, in run_until_complete
    self.run_forever()
  File "/usr/lib/python3.11/asyncio/base_events.py", line 607, in run_forever
    self._run_once()
  File "/usr/lib/python3.11/asyncio/base_events.py", line 1922, in _run_once
    handle._run()
  File "/usr/lib/python3.11/asyncio/events.py", line 80, in _run
    self._context.run(self._callback, *self._args)
  File "/home/lucassukeunkim/myenv/lib/python3.11/site-packages/discord/client.py", line 449, in _run_event
    await coro(*args, **kwargs)
  File "/home/lucassukeunkim/scuffed_discord_bot/bot.py", line 48, in on_message
    await bot.process_commands(message)
  File "/home/lucassukeunkim/myenv/lib/python3.11/site-packages/discord/ext/commands/bot.py", line 1408, in process_commands
    await self.invoke(ctx)  # type: ignore
  File "/home/lucassukeunkim/myenv/lib/python3.11/site-packages/discord/ext/commands/bot.py", line 1366, in invoke
    await ctx.command.invoke(ctx)
  File "/home/lucassukeunkim/myenv/lib/python3.11/site-packages/discord/ext/commands/core.py", line 1029, in invoke
    await injected(*ctx.args, **ctx.kwargs)  # type: ignore
  File "/home/lucassukeunkim/myenv/lib/python3.11/site-packages/discord/ext/commands/core.py", line 235, in wrapped
    ret = await coro(*args, **kwargs)
  File "/home/lucassukeunkim/scuffed_discord_bot/bot.py", line 580, in pushtextfiles
    subprocess.run(["git", "fetch"], check=True)
  File "/usr/lib/python3.11/subprocess.py", line 550, in run
    stdout, stderr = process.communicate(input, timeout=timeout)
  File "/usr/lib/python3.11/subprocess.py", line 1199, in communicate
    self.wait()
  File "/usr/lib/python3.11/subprocess.py", line 1262, in wait
    return self._wait(timeout=timeout)
  File "/usr/lib/python3.11/subprocess.py", line 1997, in _wait
    (pid, sts) = self._try_wait(0)
  File "/usr/lib/python3.11/subprocess.py", line 1955, in _try_wait
    (pid, sts) = os.waitpid(self.pid, wait_flags)

[2025-02-16 08:34:23] [WARNING ] discord.gateway: Shard ID None heartbeat blocked for more than 370 seconds.
Loop thread traceback (most recent call last):
  File "/home/lucassukeunkim/scuffed_discord_bot/bot.py", line 682, in <module>
    bot.run(BOT_TOKEN, reconnect=True)
  File "/home/lucassukeunkim/myenv/lib/python3.11/site-packages/discord/client.py", line 869, in run
    asyncio.run(runner())
  File "/usr/lib/python3.11/asyncio/runners.py", line 190, in run
    return runner.run(main)
  File "/usr/lib/python3.11/asyncio/runners.py", line 118, in run
    return self._loop.run_until_complete(task)
  File "/usr/lib/python3.11/asyncio/base_events.py", line 640, in run_until_complete
    self.run_forever()
  File "/usr/lib/python3.11/asyncio/base_events.py", line 607, in run_forever
    self._run_once()
  File "/usr/lib/python3.11/asyncio/base_events.py", line 1922, in _run_once
    handle._run()
  File "/usr/lib/python3.11/asyncio/events.py", line 80, in _run
    self._context.run(self._callback, *self._args)
  File "/home/lucassukeunkim/myenv/lib/python3.11/site-packages/discord/client.py", line 449, in _run_event
    await coro(*args, **kwargs)
  File "/home/lucassukeunkim/scuffed_discord_bot/bot.py", line 48, in on_message
    await bot.process_commands(message)
  File "/home/lucassukeunkim/myenv/lib/python3.11/site-packages/discord/ext/commands/bot.py", line 1408, in process_commands
    await self.invoke(ctx)  # type: ignore
  File "/home/lucassukeunkim/myenv/lib/python3.11/site-packages/discord/ext/commands/bot.py", line 1366, in invoke
    await ctx.command.invoke(ctx)
  File "/home/lucassukeunkim/myenv/lib/python3.11/site-packages/discord/ext/commands/core.py", line 1029, in invoke
    await injected(*ctx.args, **ctx.kwargs)  # type: ignore
  File "/home/lucassukeunkim/myenv/lib/python3.11/site-packages/discord/ext/commands/core.py", line 235, in wrapped
    ret = await coro(*args, **kwargs)
  File "/home/lucassukeunkim/scuffed_discord_bot/bot.py", line 580, in pushtextfiles
    subprocess.run(["git", "fetch"], check=True)
  File "/usr/lib/python3.11/subprocess.py", line 550, in run
    stdout, stderr = process.communicate(input, timeout=timeout)
  File "/usr/lib/python3.11/subprocess.py", line 1199, in communicate
    self.wait()
  File "/usr/lib/python3.11/subprocess.py", line 1262, in wait
    return self._wait(timeout=timeout)
  File "/usr/lib/python3.11/subprocess.py", line 1997, in _wait
    (pid, sts) = self._try_wait(0)
  File "/usr/lib/python3.11/subprocess.py", line 1955, in _try_wait
    (pid, sts) = os.waitpid(self.pid, wait_flags)

[2025-02-16 08:34:33] [WARNING ] discord.gateway: Shard ID None heartbeat blocked for more than 380 seconds.
Loop thread traceback (most recent call last):
  File "/home/lucassukeunkim/scuffed_discord_bot/bot.py", line 682, in <module>
    bot.run(BOT_TOKEN, reconnect=True)
  File "/home/lucassukeunkim/myenv/lib/python3.11/site-packages/discord/client.py", line 869, in run
    asyncio.run(runner())
  File "/usr/lib/python3.11/asyncio/runners.py", line 190, in run
    return runner.run(main)
  File "/usr/lib/python3.11/asyncio/runners.py", line 118, in run
    return self._loop.run_until_complete(task)
  File "/usr/lib/python3.11/asyncio/base_events.py", line 640, in run_until_complete
    self.run_forever()
  File "/usr/lib/python3.11/asyncio/base_events.py", line 607, in run_forever
    self._run_once()
  File "/usr/lib/python3.11/asyncio/base_events.py", line 1922, in _run_once
    handle._run()
  File "/usr/lib/python3.11/asyncio/events.py", line 80, in _run
    self._context.run(self._callback, *self._args)
  File "/home/lucassukeunkim/myenv/lib/python3.11/site-packages/discord/client.py", line 449, in _run_event
    await coro(*args, **kwargs)
  File "/home/lucassukeunkim/scuffed_discord_bot/bot.py", line 48, in on_message
    await bot.process_commands(message)
  File "/home/lucassukeunkim/myenv/lib/python3.11/site-packages/discord/ext/commands/bot.py", line 1408, in process_commands
    await self.invoke(ctx)  # type: ignore
  File "/home/lucassukeunkim/myenv/lib/python3.11/site-packages/discord/ext/commands/bot.py", line 1366, in invoke
    await ctx.command.invoke(ctx)
  File "/home/lucassukeunkim/myenv/lib/python3.11/site-packages/discord/ext/commands/core.py", line 1029, in invoke
    await injected(*ctx.args, **ctx.kwargs)  # type: ignore
  File "/home/lucassukeunkim/myenv/lib/python3.11/site-packages/discord/ext/commands/core.py", line 235, in wrapped
    ret = await coro(*args, **kwargs)
  File "/home/lucassukeunkim/scuffed_discord_bot/bot.py", line 580, in pushtextfiles
    subprocess.run(["git", "fetch"], check=True)
  File "/usr/lib/python3.11/subprocess.py", line 550, in run
    stdout, stderr = process.communicate(input, timeout=timeout)
  File "/usr/lib/python3.11/subprocess.py", line 1199, in communicate
    self.wait()
  File "/usr/lib/python3.11/subprocess.py", line 1262, in wait
    return self._wait(timeout=timeout)
  File "/usr/lib/python3.11/subprocess.py", line 1997, in _wait
    (pid, sts) = self._try_wait(0)
  File "/usr/lib/python3.11/subprocess.py", line 1955, in _try_wait
    (pid, sts) = os.waitpid(self.pid, wait_flags)

[2025-02-16 08:34:43] [WARNING ] discord.gateway: Shard ID None heartbeat blocked for more than 390 seconds.
Loop thread traceback (most recent call last):
  File "/home/lucassukeunkim/scuffed_discord_bot/bot.py", line 682, in <module>
    bot.run(BOT_TOKEN, reconnect=True)
  File "/home/lucassukeunkim/myenv/lib/python3.11/site-packages/discord/client.py", line 869, in run
    asyncio.run(runner())
  File "/usr/lib/python3.11/asyncio/runners.py", line 190, in run
    return runner.run(main)
  File "/usr/lib/python3.11/asyncio/runners.py", line 118, in run
    return self._loop.run_until_complete(task)
  File "/usr/lib/python3.11/asyncio/base_events.py", line 640, in run_until_complete
    self.run_forever()
  File "/usr/lib/python3.11/asyncio/base_events.py", line 607, in run_forever
    self._run_once()
  File "/usr/lib/python3.11/asyncio/base_events.py", line 1922, in _run_once
    handle._run()
  File "/usr/lib/python3.11/asyncio/events.py", line 80, in _run
    self._context.run(self._callback, *self._args)
  File "/home/lucassukeunkim/myenv/lib/python3.11/site-packages/discord/client.py", line 449, in _run_event
    await coro(*args, **kwargs)
  File "/home/lucassukeunkim/scuffed_discord_bot/bot.py", line 48, in on_message
    await bot.process_commands(message)
  File "/home/lucassukeunkim/myenv/lib/python3.11/site-packages/discord/ext/commands/bot.py", line 1408, in process_commands
    await self.invoke(ctx)  # type: ignore
  File "/home/lucassukeunkim/myenv/lib/python3.11/site-packages/discord/ext/commands/bot.py", line 1366, in invoke
    await ctx.command.invoke(ctx)
  File "/home/lucassukeunkim/myenv/lib/python3.11/site-packages/discord/ext/commands/core.py", line 1029, in invoke
    await injected(*ctx.args, **ctx.kwargs)  # type: ignore
  File "/home/lucassukeunkim/myenv/lib/python3.11/site-packages/discord/ext/commands/core.py", line 235, in wrapped
    ret = await coro(*args, **kwargs)
  File "/home/lucassukeunkim/scuffed_discord_bot/bot.py", line 580, in pushtextfiles
    subprocess.run(["git", "fetch"], check=True)
  File "/usr/lib/python3.11/subprocess.py", line 550, in run
    stdout, stderr = process.communicate(input, timeout=timeout)
  File "/usr/lib/python3.11/subprocess.py", line 1199, in communicate
    self.wait()
  File "/usr/lib/python3.11/subprocess.py", line 1262, in wait
    return self._wait(timeout=timeout)
  File "/usr/lib/python3.11/subprocess.py", line 1997, in _wait
    (pid, sts) = self._try_wait(0)
  File "/usr/lib/python3.11/subprocess.py", line 1955, in _try_wait
    (pid, sts) = os.waitpid(self.pid, wait_flags)

[2025-02-16 08:34:53] [WARNING ] discord.gateway: Shard ID None heartbeat blocked for more than 400 seconds.
Loop thread traceback (most recent call last):
  File "/home/lucassukeunkim/scuffed_discord_bot/bot.py", line 682, in <module>
    bot.run(BOT_TOKEN, reconnect=True)
  File "/home/lucassukeunkim/myenv/lib/python3.11/site-packages/discord/client.py", line 869, in run
    asyncio.run(runner())
  File "/usr/lib/python3.11/asyncio/runners.py", line 190, in run
    return runner.run(main)
  File "/usr/lib/python3.11/asyncio/runners.py", line 118, in run
    return self._loop.run_until_complete(task)
  File "/usr/lib/python3.11/asyncio/base_events.py", line 640, in run_until_complete
    self.run_forever()
  File "/usr/lib/python3.11/asyncio/base_events.py", line 607, in run_forever
    self._run_once()
  File "/usr/lib/python3.11/asyncio/base_events.py", line 1922, in _run_once
    handle._run()
  File "/usr/lib/python3.11/asyncio/events.py", line 80, in _run
    self._context.run(self._callback, *self._args)
  File "/home/lucassukeunkim/myenv/lib/python3.11/site-packages/discord/client.py", line 449, in _run_event
    await coro(*args, **kwargs)
  File "/home/lucassukeunkim/scuffed_discord_bot/bot.py", line 48, in on_message
    await bot.process_commands(message)
  File "/home/lucassukeunkim/myenv/lib/python3.11/site-packages/discord/ext/commands/bot.py", line 1408, in process_commands
    await self.invoke(ctx)  # type: ignore
  File "/home/lucassukeunkim/myenv/lib/python3.11/site-packages/discord/ext/commands/bot.py", line 1366, in invoke
    await ctx.command.invoke(ctx)
  File "/home/lucassukeunkim/myenv/lib/python3.11/site-packages/discord/ext/commands/core.py", line 1029, in invoke
    await injected(*ctx.args, **ctx.kwargs)  # type: ignore
  File "/home/lucassukeunkim/myenv/lib/python3.11/site-packages/discord/ext/commands/core.py", line 235, in wrapped
    ret = await coro(*args, **kwargs)
  File "/home/lucassukeunkim/scuffed_discord_bot/bot.py", line 580, in pushtextfiles
    subprocess.run(["git", "fetch"], check=True)
  File "/usr/lib/python3.11/subprocess.py", line 550, in run
    stdout, stderr = process.communicate(input, timeout=timeout)
  File "/usr/lib/python3.11/subprocess.py", line 1199, in communicate
    self.wait()
  File "/usr/lib/python3.11/subprocess.py", line 1262, in wait
    return self._wait(timeout=timeout)
  File "/usr/lib/python3.11/subprocess.py", line 1997, in _wait
    (pid, sts) = self._try_wait(0)
  File "/usr/lib/python3.11/subprocess.py", line 1955, in _try_wait
    (pid, sts) = os.waitpid(self.pid, wait_flags)

[2025-02-16 08:35:03] [WARNING ] discord.gateway: Shard ID None heartbeat blocked for more than 410 seconds.
Loop thread traceback (most recent call last):
  File "/home/lucassukeunkim/scuffed_discord_bot/bot.py", line 682, in <module>
    bot.run(BOT_TOKEN, reconnect=True)
  File "/home/lucassukeunkim/myenv/lib/python3.11/site-packages/discord/client.py", line 869, in run
    asyncio.run(runner())
  File "/usr/lib/python3.11/asyncio/runners.py", line 190, in run
    return runner.run(main)
  File "/usr/lib/python3.11/asyncio/runners.py", line 118, in run
    return self._loop.run_until_complete(task)
  File "/usr/lib/python3.11/asyncio/base_events.py", line 640, in run_until_complete
    self.run_forever()
  File "/usr/lib/python3.11/asyncio/base_events.py", line 607, in run_forever
    self._run_once()
  File "/usr/lib/python3.11/asyncio/base_events.py", line 1922, in _run_once
    handle._run()
  File "/usr/lib/python3.11/asyncio/events.py", line 80, in _run
    self._context.run(self._callback, *self._args)
  File "/home/lucassukeunkim/myenv/lib/python3.11/site-packages/discord/client.py", line 449, in _run_event
    await coro(*args, **kwargs)
  File "/home/lucassukeunkim/scuffed_discord_bot/bot.py", line 48, in on_message
    await bot.process_commands(message)
  File "/home/lucassukeunkim/myenv/lib/python3.11/site-packages/discord/ext/commands/bot.py", line 1408, in process_commands
    await self.invoke(ctx)  # type: ignore
  File "/home/lucassukeunkim/myenv/lib/python3.11/site-packages/discord/ext/commands/bot.py", line 1366, in invoke
    await ctx.command.invoke(ctx)
  File "/home/lucassukeunkim/myenv/lib/python3.11/site-packages/discord/ext/commands/core.py", line 1029, in invoke
    await injected(*ctx.args, **ctx.kwargs)  # type: ignore
  File "/home/lucassukeunkim/myenv/lib/python3.11/site-packages/discord/ext/commands/core.py", line 235, in wrapped
    ret = await coro(*args, **kwargs)
  File "/home/lucassukeunkim/scuffed_discord_bot/bot.py", line 580, in pushtextfiles
    subprocess.run(["git", "fetch"], check=True)
  File "/usr/lib/python3.11/subprocess.py", line 550, in run
    stdout, stderr = process.communicate(input, timeout=timeout)
  File "/usr/lib/python3.11/subprocess.py", line 1199, in communicate
    self.wait()
  File "/usr/lib/python3.11/subprocess.py", line 1262, in wait
    return self._wait(timeout=timeout)
  File "/usr/lib/python3.11/subprocess.py", line 1997, in _wait
    (pid, sts) = self._try_wait(0)
  File "/usr/lib/python3.11/subprocess.py", line 1955, in _try_wait
    (pid, sts) = os.waitpid(self.pid, wait_flags)

[2025-02-16 08:35:13] [WARNING ] discord.gateway: Shard ID None heartbeat blocked for more than 420 seconds.
Loop thread traceback (most recent call last):
  File "/home/lucassukeunkim/scuffed_discord_bot/bot.py", line 682, in <module>
    bot.run(BOT_TOKEN, reconnect=True)
  File "/home/lucassukeunkim/myenv/lib/python3.11/site-packages/discord/client.py", line 869, in run
    asyncio.run(runner())
  File "/usr/lib/python3.11/asyncio/runners.py", line 190, in run
    return runner.run(main)
  File "/usr/lib/python3.11/asyncio/runners.py", line 118, in run
    return self._loop.run_until_complete(task)
  File "/usr/lib/python3.11/asyncio/base_events.py", line 640, in run_until_complete
    self.run_forever()
  File "/usr/lib/python3.11/asyncio/base_events.py", line 607, in run_forever
    self._run_once()
  File "/usr/lib/python3.11/asyncio/base_events.py", line 1922, in _run_once
    handle._run()
  File "/usr/lib/python3.11/asyncio/events.py", line 80, in _run
    self._context.run(self._callback, *self._args)
  File "/home/lucassukeunkim/myenv/lib/python3.11/site-packages/discord/client.py", line 449, in _run_event
    await coro(*args, **kwargs)
  File "/home/lucassukeunkim/scuffed_discord_bot/bot.py", line 48, in on_message
    await bot.process_commands(message)
  File "/home/lucassukeunkim/myenv/lib/python3.11/site-packages/discord/ext/commands/bot.py", line 1408, in process_commands
    await self.invoke(ctx)  # type: ignore
  File "/home/lucassukeunkim/myenv/lib/python3.11/site-packages/discord/ext/commands/bot.py", line 1366, in invoke
    await ctx.command.invoke(ctx)
  File "/home/lucassukeunkim/myenv/lib/python3.11/site-packages/discord/ext/commands/core.py", line 1029, in invoke
    await injected(*ctx.args, **ctx.kwargs)  # type: ignore
  File "/home/lucassukeunkim/myenv/lib/python3.11/site-packages/discord/ext/commands/core.py", line 235, in wrapped
    ret = await coro(*args, **kwargs)
  File "/home/lucassukeunkim/scuffed_discord_bot/bot.py", line 580, in pushtextfiles
    subprocess.run(["git", "fetch"], check=True)
  File "/usr/lib/python3.11/subprocess.py", line 550, in run
    stdout, stderr = process.communicate(input, timeout=timeout)
  File "/usr/lib/python3.11/subprocess.py", line 1199, in communicate
    self.wait()
  File "/usr/lib/python3.11/subprocess.py", line 1262, in wait
    return self._wait(timeout=timeout)
  File "/usr/lib/python3.11/subprocess.py", line 1997, in _wait
    (pid, sts) = self._try_wait(0)
  File "/usr/lib/python3.11/subprocess.py", line 1955, in _try_wait
    (pid, sts) = os.waitpid(self.pid, wait_flags)

[2025-02-16 08:35:23] [WARNING ] discord.gateway: Shard ID None heartbeat blocked for more than 430 seconds.
Loop thread traceback (most recent call last):
  File "/home/lucassukeunkim/scuffed_discord_bot/bot.py", line 682, in <module>
    bot.run(BOT_TOKEN, reconnect=True)
  File "/home/lucassukeunkim/myenv/lib/python3.11/site-packages/discord/client.py", line 869, in run
    asyncio.run(runner())
  File "/usr/lib/python3.11/asyncio/runners.py", line 190, in run
    return runner.run(main)
  File "/usr/lib/python3.11/asyncio/runners.py", line 118, in run
    return self._loop.run_until_complete(task)
  File "/usr/lib/python3.11/asyncio/base_events.py", line 640, in run_until_complete
    self.run_forever()
  File "/usr/lib/python3.11/asyncio/base_events.py", line 607, in run_forever
    self._run_once()
  File "/usr/lib/python3.11/asyncio/base_events.py", line 1922, in _run_once
    handle._run()
  File "/usr/lib/python3.11/asyncio/events.py", line 80, in _run
    self._context.run(self._callback, *self._args)
  File "/home/lucassukeunkim/myenv/lib/python3.11/site-packages/discord/client.py", line 449, in _run_event
    await coro(*args, **kwargs)
  File "/home/lucassukeunkim/scuffed_discord_bot/bot.py", line 48, in on_message
    await bot.process_commands(message)
  File "/home/lucassukeunkim/myenv/lib/python3.11/site-packages/discord/ext/commands/bot.py", line 1408, in process_commands
    await self.invoke(ctx)  # type: ignore
  File "/home/lucassukeunkim/myenv/lib/python3.11/site-packages/discord/ext/commands/bot.py", line 1366, in invoke
    await ctx.command.invoke(ctx)
  File "/home/lucassukeunkim/myenv/lib/python3.11/site-packages/discord/ext/commands/core.py", line 1029, in invoke
    await injected(*ctx.args, **ctx.kwargs)  # type: ignore
  File "/home/lucassukeunkim/myenv/lib/python3.11/site-packages/discord/ext/commands/core.py", line 235, in wrapped
    ret = await coro(*args, **kwargs)
  File "/home/lucassukeunkim/scuffed_discord_bot/bot.py", line 580, in pushtextfiles
    subprocess.run(["git", "fetch"], check=True)
  File "/usr/lib/python3.11/subprocess.py", line 550, in run
    stdout, stderr = process.communicate(input, timeout=timeout)
  File "/usr/lib/python3.11/subprocess.py", line 1199, in communicate
    self.wait()
  File "/usr/lib/python3.11/subprocess.py", line 1262, in wait
    return self._wait(timeout=timeout)
  File "/usr/lib/python3.11/subprocess.py", line 1997, in _wait
    (pid, sts) = self._try_wait(0)
  File "/usr/lib/python3.11/subprocess.py", line 1955, in _try_wait
    (pid, sts) = os.waitpid(self.pid, wait_flags)

[2025-02-16 08:35:33] [WARNING ] discord.gateway: Shard ID None heartbeat blocked for more than 440 seconds.
Loop thread traceback (most recent call last):
  File "/home/lucassukeunkim/scuffed_discord_bot/bot.py", line 682, in <module>
    bot.run(BOT_TOKEN, reconnect=True)
  File "/home/lucassukeunkim/myenv/lib/python3.11/site-packages/discord/client.py", line 869, in run
    asyncio.run(runner())
  File "/usr/lib/python3.11/asyncio/runners.py", line 190, in run
    return runner.run(main)
  File "/usr/lib/python3.11/asyncio/runners.py", line 118, in run
    return self._loop.run_until_complete(task)
  File "/usr/lib/python3.11/asyncio/base_events.py", line 640, in run_until_complete
    self.run_forever()
  File "/usr/lib/python3.11/asyncio/base_events.py", line 607, in run_forever
    self._run_once()
  File "/usr/lib/python3.11/asyncio/base_events.py", line 1922, in _run_once
    handle._run()
  File "/usr/lib/python3.11/asyncio/events.py", line 80, in _run
    self._context.run(self._callback, *self._args)
  File "/home/lucassukeunkim/myenv/lib/python3.11/site-packages/discord/client.py", line 449, in _run_event
    await coro(*args, **kwargs)
  File "/home/lucassukeunkim/scuffed_discord_bot/bot.py", line 48, in on_message
    await bot.process_commands(message)
  File "/home/lucassukeunkim/myenv/lib/python3.11/site-packages/discord/ext/commands/bot.py", line 1408, in process_commands
    await self.invoke(ctx)  # type: ignore
  File "/home/lucassukeunkim/myenv/lib/python3.11/site-packages/discord/ext/commands/bot.py", line 1366, in invoke
    await ctx.command.invoke(ctx)
  File "/home/lucassukeunkim/myenv/lib/python3.11/site-packages/discord/ext/commands/core.py", line 1029, in invoke
    await injected(*ctx.args, **ctx.kwargs)  # type: ignore
  File "/home/lucassukeunkim/myenv/lib/python3.11/site-packages/discord/ext/commands/core.py", line 235, in wrapped
    ret = await coro(*args, **kwargs)
  File "/home/lucassukeunkim/scuffed_discord_bot/bot.py", line 580, in pushtextfiles
    subprocess.run(["git", "fetch"], check=True)
  File "/usr/lib/python3.11/subprocess.py", line 550, in run
    stdout, stderr = process.communicate(input, timeout=timeout)
  File "/usr/lib/python3.11/subprocess.py", line 1199, in communicate
    self.wait()
  File "/usr/lib/python3.11/subprocess.py", line 1262, in wait
    return self._wait(timeout=timeout)
  File "/usr/lib/python3.11/subprocess.py", line 1997, in _wait
    (pid, sts) = self._try_wait(0)
  File "/usr/lib/python3.11/subprocess.py", line 1955, in _try_wait
    (pid, sts) = os.waitpid(self.pid, wait_flags)

[2025-02-16 08:35:43] [WARNING ] discord.gateway: Shard ID None heartbeat blocked for more than 450 seconds.
Loop thread traceback (most recent call last):
  File "/home/lucassukeunkim/scuffed_discord_bot/bot.py", line 682, in <module>
    bot.run(BOT_TOKEN, reconnect=True)
  File "/home/lucassukeunkim/myenv/lib/python3.11/site-packages/discord/client.py", line 869, in run
    asyncio.run(runner())
  File "/usr/lib/python3.11/asyncio/runners.py", line 190, in run
    return runner.run(main)
  File "/usr/lib/python3.11/asyncio/runners.py", line 118, in run
    return self._loop.run_until_complete(task)
  File "/usr/lib/python3.11/asyncio/base_events.py", line 640, in run_until_complete
    self.run_forever()
  File "/usr/lib/python3.11/asyncio/base_events.py", line 607, in run_forever
    self._run_once()
  File "/usr/lib/python3.11/asyncio/base_events.py", line 1922, in _run_once
    handle._run()
  File "/usr/lib/python3.11/asyncio/events.py", line 80, in _run
    self._context.run(self._callback, *self._args)
  File "/home/lucassukeunkim/myenv/lib/python3.11/site-packages/discord/client.py", line 449, in _run_event
    await coro(*args, **kwargs)
  File "/home/lucassukeunkim/scuffed_discord_bot/bot.py", line 48, in on_message
    await bot.process_commands(message)
  File "/home/lucassukeunkim/myenv/lib/python3.11/site-packages/discord/ext/commands/bot.py", line 1408, in process_commands
    await self.invoke(ctx)  # type: ignore
  File "/home/lucassukeunkim/myenv/lib/python3.11/site-packages/discord/ext/commands/bot.py", line 1366, in invoke
    await ctx.command.invoke(ctx)
  File "/home/lucassukeunkim/myenv/lib/python3.11/site-packages/discord/ext/commands/core.py", line 1029, in invoke
    await injected(*ctx.args, **ctx.kwargs)  # type: ignore
  File "/home/lucassukeunkim/myenv/lib/python3.11/site-packages/discord/ext/commands/core.py", line 235, in wrapped
    ret = await coro(*args, **kwargs)
  File "/home/lucassukeunkim/scuffed_discord_bot/bot.py", line 580, in pushtextfiles
    subprocess.run(["git", "fetch"], check=True)
  File "/usr/lib/python3.11/subprocess.py", line 550, in run
    stdout, stderr = process.communicate(input, timeout=timeout)
  File "/usr/lib/python3.11/subprocess.py", line 1199, in communicate
    self.wait()
  File "/usr/lib/python3.11/subprocess.py", line 1262, in wait
    return self._wait(timeout=timeout)
  File "/usr/lib/python3.11/subprocess.py", line 1997, in _wait
    (pid, sts) = self._try_wait(0)
  File "/usr/lib/python3.11/subprocess.py", line 1955, in _try_wait
    (pid, sts) = os.waitpid(self.pid, wait_flags)

[2025-02-16 08:35:53] [WARNING ] discord.gateway: Shard ID None heartbeat blocked for more than 460 seconds.
Loop thread traceback (most recent call last):
  File "/home/lucassukeunkim/scuffed_discord_bot/bot.py", line 682, in <module>
    bot.run(BOT_TOKEN, reconnect=True)
  File "/home/lucassukeunkim/myenv/lib/python3.11/site-packages/discord/client.py", line 869, in run
    asyncio.run(runner())
  File "/usr/lib/python3.11/asyncio/runners.py", line 190, in run
    return runner.run(main)
  File "/usr/lib/python3.11/asyncio/runners.py", line 118, in run
    return self._loop.run_until_complete(task)
  File "/usr/lib/python3.11/asyncio/base_events.py", line 640, in run_until_complete
    self.run_forever()
  File "/usr/lib/python3.11/asyncio/base_events.py", line 607, in run_forever
    self._run_once()
  File "/usr/lib/python3.11/asyncio/base_events.py", line 1922, in _run_once
    handle._run()
  File "/usr/lib/python3.11/asyncio/events.py", line 80, in _run
    self._context.run(self._callback, *self._args)
  File "/home/lucassukeunkim/myenv/lib/python3.11/site-packages/discord/client.py", line 449, in _run_event
    await coro(*args, **kwargs)
  File "/home/lucassukeunkim/scuffed_discord_bot/bot.py", line 48, in on_message
    await bot.process_commands(message)
  File "/home/lucassukeunkim/myenv/lib/python3.11/site-packages/discord/ext/commands/bot.py", line 1408, in process_commands
    await self.invoke(ctx)  # type: ignore
  File "/home/lucassukeunkim/myenv/lib/python3.11/site-packages/discord/ext/commands/bot.py", line 1366, in invoke
    await ctx.command.invoke(ctx)
  File "/home/lucassukeunkim/myenv/lib/python3.11/site-packages/discord/ext/commands/core.py", line 1029, in invoke
    await injected(*ctx.args, **ctx.kwargs)  # type: ignore
  File "/home/lucassukeunkim/myenv/lib/python3.11/site-packages/discord/ext/commands/core.py", line 235, in wrapped
    ret = await coro(*args, **kwargs)
  File "/home/lucassukeunkim/scuffed_discord_bot/bot.py", line 580, in pushtextfiles
    subprocess.run(["git", "fetch"], check=True)
  File "/usr/lib/python3.11/subprocess.py", line 550, in run
    stdout, stderr = process.communicate(input, timeout=timeout)
  File "/usr/lib/python3.11/subprocess.py", line 1199, in communicate
    self.wait()
  File "/usr/lib/python3.11/subprocess.py", line 1262, in wait
    return self._wait(timeout=timeout)
  File "/usr/lib/python3.11/subprocess.py", line 1997, in _wait
    (pid, sts) = self._try_wait(0)
  File "/usr/lib/python3.11/subprocess.py", line 1955, in _try_wait
    (pid, sts) = os.waitpid(self.pid, wait_flags)

[2025-02-16 08:36:03] [WARNING ] discord.gateway: Shard ID None heartbeat blocked for more than 470 seconds.
Loop thread traceback (most recent call last):
  File "/home/lucassukeunkim/scuffed_discord_bot/bot.py", line 682, in <module>
    bot.run(BOT_TOKEN, reconnect=True)
  File "/home/lucassukeunkim/myenv/lib/python3.11/site-packages/discord/client.py", line 869, in run
    asyncio.run(runner())
  File "/usr/lib/python3.11/asyncio/runners.py", line 190, in run
    return runner.run(main)
  File "/usr/lib/python3.11/asyncio/runners.py", line 118, in run
    return self._loop.run_until_complete(task)
  File "/usr/lib/python3.11/asyncio/base_events.py", line 640, in run_until_complete
    self.run_forever()
  File "/usr/lib/python3.11/asyncio/base_events.py", line 607, in run_forever
    self._run_once()
  File "/usr/lib/python3.11/asyncio/base_events.py", line 1922, in _run_once
    handle._run()
  File "/usr/lib/python3.11/asyncio/events.py", line 80, in _run
    self._context.run(self._callback, *self._args)
  File "/home/lucassukeunkim/myenv/lib/python3.11/site-packages/discord/client.py", line 449, in _run_event
    await coro(*args, **kwargs)
  File "/home/lucassukeunkim/scuffed_discord_bot/bot.py", line 48, in on_message
    await bot.process_commands(message)
  File "/home/lucassukeunkim/myenv/lib/python3.11/site-packages/discord/ext/commands/bot.py", line 1408, in process_commands
    await self.invoke(ctx)  # type: ignore
  File "/home/lucassukeunkim/myenv/lib/python3.11/site-packages/discord/ext/commands/bot.py", line 1366, in invoke
    await ctx.command.invoke(ctx)
  File "/home/lucassukeunkim/myenv/lib/python3.11/site-packages/discord/ext/commands/core.py", line 1029, in invoke
    await injected(*ctx.args, **ctx.kwargs)  # type: ignore
  File "/home/lucassukeunkim/myenv/lib/python3.11/site-packages/discord/ext/commands/core.py", line 235, in wrapped
    ret = await coro(*args, **kwargs)
  File "/home/lucassukeunkim/scuffed_discord_bot/bot.py", line 580, in pushtextfiles
    subprocess.run(["git", "fetch"], check=True)
  File "/usr/lib/python3.11/subprocess.py", line 550, in run
    stdout, stderr = process.communicate(input, timeout=timeout)
  File "/usr/lib/python3.11/subprocess.py", line 1199, in communicate
    self.wait()
  File "/usr/lib/python3.11/subprocess.py", line 1262, in wait
    return self._wait(timeout=timeout)
  File "/usr/lib/python3.11/subprocess.py", line 1997, in _wait
    (pid, sts) = self._try_wait(0)
  File "/usr/lib/python3.11/subprocess.py", line 1955, in _try_wait
    (pid, sts) = os.waitpid(self.pid, wait_flags)

[2025-02-16 08:36:13] [WARNING ] discord.gateway: Shard ID None heartbeat blocked for more than 480 seconds.
Loop thread traceback (most recent call last):
  File "/home/lucassukeunkim/scuffed_discord_bot/bot.py", line 682, in <module>
    bot.run(BOT_TOKEN, reconnect=True)
  File "/home/lucassukeunkim/myenv/lib/python3.11/site-packages/discord/client.py", line 869, in run
    asyncio.run(runner())
  File "/usr/lib/python3.11/asyncio/runners.py", line 190, in run
    return runner.run(main)
  File "/usr/lib/python3.11/asyncio/runners.py", line 118, in run
    return self._loop.run_until_complete(task)
  File "/usr/lib/python3.11/asyncio/base_events.py", line 640, in run_until_complete
    self.run_forever()
  File "/usr/lib/python3.11/asyncio/base_events.py", line 607, in run_forever
    self._run_once()
  File "/usr/lib/python3.11/asyncio/base_events.py", line 1922, in _run_once
    handle._run()
  File "/usr/lib/python3.11/asyncio/events.py", line 80, in _run
    self._context.run(self._callback, *self._args)
  File "/home/lucassukeunkim/myenv/lib/python3.11/site-packages/discord/client.py", line 449, in _run_event
    await coro(*args, **kwargs)
  File "/home/lucassukeunkim/scuffed_discord_bot/bot.py", line 48, in on_message
    await bot.process_commands(message)
  File "/home/lucassukeunkim/myenv/lib/python3.11/site-packages/discord/ext/commands/bot.py", line 1408, in process_commands
    await self.invoke(ctx)  # type: ignore
  File "/home/lucassukeunkim/myenv/lib/python3.11/site-packages/discord/ext/commands/bot.py", line 1366, in invoke
    await ctx.command.invoke(ctx)
  File "/home/lucassukeunkim/myenv/lib/python3.11/site-packages/discord/ext/commands/core.py", line 1029, in invoke
    await injected(*ctx.args, **ctx.kwargs)  # type: ignore
  File "/home/lucassukeunkim/myenv/lib/python3.11/site-packages/discord/ext/commands/core.py", line 235, in wrapped
    ret = await coro(*args, **kwargs)
  File "/home/lucassukeunkim/scuffed_discord_bot/bot.py", line 580, in pushtextfiles
    subprocess.run(["git", "fetch"], check=True)
  File "/usr/lib/python3.11/subprocess.py", line 550, in run
    stdout, stderr = process.communicate(input, timeout=timeout)
  File "/usr/lib/python3.11/subprocess.py", line 1199, in communicate
    self.wait()
  File "/usr/lib/python3.11/subprocess.py", line 1262, in wait
    return self._wait(timeout=timeout)
  File "/usr/lib/python3.11/subprocess.py", line 1997, in _wait
    (pid, sts) = self._try_wait(0)
  File "/usr/lib/python3.11/subprocess.py", line 1955, in _try_wait
    (pid, sts) = os.waitpid(self.pid, wait_flags)

[2025-02-16 08:36:23] [WARNING ] discord.gateway: Shard ID None heartbeat blocked for more than 490 seconds.
Loop thread traceback (most recent call last):
  File "/home/lucassukeunkim/scuffed_discord_bot/bot.py", line 682, in <module>
    bot.run(BOT_TOKEN, reconnect=True)
  File "/home/lucassukeunkim/myenv/lib/python3.11/site-packages/discord/client.py", line 869, in run
    asyncio.run(runner())
  File "/usr/lib/python3.11/asyncio/runners.py", line 190, in run
    return runner.run(main)
  File "/usr/lib/python3.11/asyncio/runners.py", line 118, in run
    return self._loop.run_until_complete(task)
  File "/usr/lib/python3.11/asyncio/base_events.py", line 640, in run_until_complete
    self.run_forever()
  File "/usr/lib/python3.11/asyncio/base_events.py", line 607, in run_forever
    self._run_once()
  File "/usr/lib/python3.11/asyncio/base_events.py", line 1922, in _run_once
    handle._run()
  File "/usr/lib/python3.11/asyncio/events.py", line 80, in _run
    self._context.run(self._callback, *self._args)
  File "/home/lucassukeunkim/myenv/lib/python3.11/site-packages/discord/client.py", line 449, in _run_event
    await coro(*args, **kwargs)
  File "/home/lucassukeunkim/scuffed_discord_bot/bot.py", line 48, in on_message
    await bot.process_commands(message)
  File "/home/lucassukeunkim/myenv/lib/python3.11/site-packages/discord/ext/commands/bot.py", line 1408, in process_commands
    await self.invoke(ctx)  # type: ignore
  File "/home/lucassukeunkim/myenv/lib/python3.11/site-packages/discord/ext/commands/bot.py", line 1366, in invoke
    await ctx.command.invoke(ctx)
  File "/home/lucassukeunkim/myenv/lib/python3.11/site-packages/discord/ext/commands/core.py", line 1029, in invoke
    await injected(*ctx.args, **ctx.kwargs)  # type: ignore
  File "/home/lucassukeunkim/myenv/lib/python3.11/site-packages/discord/ext/commands/core.py", line 235, in wrapped
    ret = await coro(*args, **kwargs)
  File "/home/lucassukeunkim/scuffed_discord_bot/bot.py", line 580, in pushtextfiles
    subprocess.run(["git", "fetch"], check=True)
  File "/usr/lib/python3.11/subprocess.py", line 550, in run
    stdout, stderr = process.communicate(input, timeout=timeout)
  File "/usr/lib/python3.11/subprocess.py", line 1199, in communicate
    self.wait()
  File "/usr/lib/python3.11/subprocess.py", line 1262, in wait
    return self._wait(timeout=timeout)
  File "/usr/lib/python3.11/subprocess.py", line 1997, in _wait
    (pid, sts) = self._try_wait(0)
  File "/usr/lib/python3.11/subprocess.py", line 1955, in _try_wait
    (pid, sts) = os.waitpid(self.pid, wait_flags)

[2025-02-16 08:36:33] [WARNING ] discord.gateway: Shard ID None heartbeat blocked for more than 500 seconds.
Loop thread traceback (most recent call last):
  File "/home/lucassukeunkim/scuffed_discord_bot/bot.py", line 682, in <module>
    bot.run(BOT_TOKEN, reconnect=True)
  File "/home/lucassukeunkim/myenv/lib/python3.11/site-packages/discord/client.py", line 869, in run
    asyncio.run(runner())
  File "/usr/lib/python3.11/asyncio/runners.py", line 190, in run
    return runner.run(main)
  File "/usr/lib/python3.11/asyncio/runners.py", line 118, in run
    return self._loop.run_until_complete(task)
  File "/usr/lib/python3.11/asyncio/base_events.py", line 640, in run_until_complete
    self.run_forever()
  File "/usr/lib/python3.11/asyncio/base_events.py", line 607, in run_forever
    self._run_once()
  File "/usr/lib/python3.11/asyncio/base_events.py", line 1922, in _run_once
    handle._run()
  File "/usr/lib/python3.11/asyncio/events.py", line 80, in _run
    self._context.run(self._callback, *self._args)
  File "/home/lucassukeunkim/myenv/lib/python3.11/site-packages/discord/client.py", line 449, in _run_event
    await coro(*args, **kwargs)
  File "/home/lucassukeunkim/scuffed_discord_bot/bot.py", line 48, in on_message
    await bot.process_commands(message)
  File "/home/lucassukeunkim/myenv/lib/python3.11/site-packages/discord/ext/commands/bot.py", line 1408, in process_commands
    await self.invoke(ctx)  # type: ignore
  File "/home/lucassukeunkim/myenv/lib/python3.11/site-packages/discord/ext/commands/bot.py", line 1366, in invoke
    await ctx.command.invoke(ctx)
  File "/home/lucassukeunkim/myenv/lib/python3.11/site-packages/discord/ext/commands/core.py", line 1029, in invoke
    await injected(*ctx.args, **ctx.kwargs)  # type: ignore
  File "/home/lucassukeunkim/myenv/lib/python3.11/site-packages/discord/ext/commands/core.py", line 235, in wrapped
    ret = await coro(*args, **kwargs)
  File "/home/lucassukeunkim/scuffed_discord_bot/bot.py", line 580, in pushtextfiles
    subprocess.run(["git", "fetch"], check=True)
  File "/usr/lib/python3.11/subprocess.py", line 550, in run
    stdout, stderr = process.communicate(input, timeout=timeout)
  File "/usr/lib/python3.11/subprocess.py", line 1199, in communicate
    self.wait()
  File "/usr/lib/python3.11/subprocess.py", line 1262, in wait
    return self._wait(timeout=timeout)
  File "/usr/lib/python3.11/subprocess.py", line 1997, in _wait
    (pid, sts) = self._try_wait(0)
  File "/usr/lib/python3.11/subprocess.py", line 1955, in _try_wait
    (pid, sts) = os.waitpid(self.pid, wait_flags)

[2025-02-16 08:36:43] [WARNING ] discord.gateway: Shard ID None heartbeat blocked for more than 510 seconds.
Loop thread traceback (most recent call last):
  File "/home/lucassukeunkim/scuffed_discord_bot/bot.py", line 682, in <module>
    bot.run(BOT_TOKEN, reconnect=True)
  File "/home/lucassukeunkim/myenv/lib/python3.11/site-packages/discord/client.py", line 869, in run
    asyncio.run(runner())
  File "/usr/lib/python3.11/asyncio/runners.py", line 190, in run
    return runner.run(main)
  File "/usr/lib/python3.11/asyncio/runners.py", line 118, in run
    return self._loop.run_until_complete(task)
  File "/usr/lib/python3.11/asyncio/base_events.py", line 640, in run_until_complete
    self.run_forever()
  File "/usr/lib/python3.11/asyncio/base_events.py", line 607, in run_forever
    self._run_once()
  File "/usr/lib/python3.11/asyncio/base_events.py", line 1922, in _run_once
    handle._run()
  File "/usr/lib/python3.11/asyncio/events.py", line 80, in _run
    self._context.run(self._callback, *self._args)
  File "/home/lucassukeunkim/myenv/lib/python3.11/site-packages/discord/client.py", line 449, in _run_event
    await coro(*args, **kwargs)
  File "/home/lucassukeunkim/scuffed_discord_bot/bot.py", line 48, in on_message
    await bot.process_commands(message)
  File "/home/lucassukeunkim/myenv/lib/python3.11/site-packages/discord/ext/commands/bot.py", line 1408, in process_commands
    await self.invoke(ctx)  # type: ignore
  File "/home/lucassukeunkim/myenv/lib/python3.11/site-packages/discord/ext/commands/bot.py", line 1366, in invoke
    await ctx.command.invoke(ctx)
  File "/home/lucassukeunkim/myenv/lib/python3.11/site-packages/discord/ext/commands/core.py", line 1029, in invoke
    await injected(*ctx.args, **ctx.kwargs)  # type: ignore
  File "/home/lucassukeunkim/myenv/lib/python3.11/site-packages/discord/ext/commands/core.py", line 235, in wrapped
    ret = await coro(*args, **kwargs)
  File "/home/lucassukeunkim/scuffed_discord_bot/bot.py", line 580, in pushtextfiles
    subprocess.run(["git", "fetch"], check=True)
  File "/usr/lib/python3.11/subprocess.py", line 550, in run
    stdout, stderr = process.communicate(input, timeout=timeout)
  File "/usr/lib/python3.11/subprocess.py", line 1199, in communicate
    self.wait()
  File "/usr/lib/python3.11/subprocess.py", line 1262, in wait
    return self._wait(timeout=timeout)
  File "/usr/lib/python3.11/subprocess.py", line 1997, in _wait
    (pid, sts) = self._try_wait(0)
  File "/usr/lib/python3.11/subprocess.py", line 1955, in _try_wait
    (pid, sts) = os.waitpid(self.pid, wait_flags)

[2025-02-16 08:36:53] [WARNING ] discord.gateway: Shard ID None heartbeat blocked for more than 520 seconds.
Loop thread traceback (most recent call last):
  File "/home/lucassukeunkim/scuffed_discord_bot/bot.py", line 682, in <module>
    bot.run(BOT_TOKEN, reconnect=True)
  File "/home/lucassukeunkim/myenv/lib/python3.11/site-packages/discord/client.py", line 869, in run
    asyncio.run(runner())
  File "/usr/lib/python3.11/asyncio/runners.py", line 190, in run
    return runner.run(main)
  File "/usr/lib/python3.11/asyncio/runners.py", line 118, in run
    return self._loop.run_until_complete(task)
  File "/usr/lib/python3.11/asyncio/base_events.py", line 640, in run_until_complete
    self.run_forever()
  File "/usr/lib/python3.11/asyncio/base_events.py", line 607, in run_forever
    self._run_once()
  File "/usr/lib/python3.11/asyncio/base_events.py", line 1922, in _run_once
    handle._run()
  File "/usr/lib/python3.11/asyncio/events.py", line 80, in _run
    self._context.run(self._callback, *self._args)
  File "/home/lucassukeunkim/myenv/lib/python3.11/site-packages/discord/client.py", line 449, in _run_event
    await coro(*args, **kwargs)
  File "/home/lucassukeunkim/scuffed_discord_bot/bot.py", line 48, in on_message
    await bot.process_commands(message)
  File "/home/lucassukeunkim/myenv/lib/python3.11/site-packages/discord/ext/commands/bot.py", line 1408, in process_commands
    await self.invoke(ctx)  # type: ignore
  File "/home/lucassukeunkim/myenv/lib/python3.11/site-packages/discord/ext/commands/bot.py", line 1366, in invoke
    await ctx.command.invoke(ctx)
  File "/home/lucassukeunkim/myenv/lib/python3.11/site-packages/discord/ext/commands/core.py", line 1029, in invoke
    await injected(*ctx.args, **ctx.kwargs)  # type: ignore
  File "/home/lucassukeunkim/myenv/lib/python3.11/site-packages/discord/ext/commands/core.py", line 235, in wrapped
    ret = await coro(*args, **kwargs)
  File "/home/lucassukeunkim/scuffed_discord_bot/bot.py", line 580, in pushtextfiles
    subprocess.run(["git", "fetch"], check=True)
  File "/usr/lib/python3.11/subprocess.py", line 550, in run
    stdout, stderr = process.communicate(input, timeout=timeout)
  File "/usr/lib/python3.11/subprocess.py", line 1199, in communicate
    self.wait()
  File "/usr/lib/python3.11/subprocess.py", line 1262, in wait
    return self._wait(timeout=timeout)
  File "/usr/lib/python3.11/subprocess.py", line 1997, in _wait
    (pid, sts) = self._try_wait(0)
  File "/usr/lib/python3.11/subprocess.py", line 1955, in _try_wait
    (pid, sts) = os.waitpid(self.pid, wait_flags)

[2025-02-16 08:37:03] [WARNING ] discord.gateway: Shard ID None heartbeat blocked for more than 530 seconds.
Loop thread traceback (most recent call last):
  File "/home/lucassukeunkim/scuffed_discord_bot/bot.py", line 682, in <module>
    bot.run(BOT_TOKEN, reconnect=True)
  File "/home/lucassukeunkim/myenv/lib/python3.11/site-packages/discord/client.py", line 869, in run
    asyncio.run(runner())
  File "/usr/lib/python3.11/asyncio/runners.py", line 190, in run
    return runner.run(main)
  File "/usr/lib/python3.11/asyncio/runners.py", line 118, in run
    return self._loop.run_until_complete(task)
  File "/usr/lib/python3.11/asyncio/base_events.py", line 640, in run_until_complete
    self.run_forever()
  File "/usr/lib/python3.11/asyncio/base_events.py", line 607, in run_forever
    self._run_once()
  File "/usr/lib/python3.11/asyncio/base_events.py", line 1922, in _run_once
    handle._run()
  File "/usr/lib/python3.11/asyncio/events.py", line 80, in _run
    self._context.run(self._callback, *self._args)
  File "/home/lucassukeunkim/myenv/lib/python3.11/site-packages/discord/client.py", line 449, in _run_event
    await coro(*args, **kwargs)
  File "/home/lucassukeunkim/scuffed_discord_bot/bot.py", line 48, in on_message
    await bot.process_commands(message)
  File "/home/lucassukeunkim/myenv/lib/python3.11/site-packages/discord/ext/commands/bot.py", line 1408, in process_commands
    await self.invoke(ctx)  # type: ignore
  File "/home/lucassukeunkim/myenv/lib/python3.11/site-packages/discord/ext/commands/bot.py", line 1366, in invoke
    await ctx.command.invoke(ctx)
  File "/home/lucassukeunkim/myenv/lib/python3.11/site-packages/discord/ext/commands/core.py", line 1029, in invoke
    await injected(*ctx.args, **ctx.kwargs)  # type: ignore
  File "/home/lucassukeunkim/myenv/lib/python3.11/site-packages/discord/ext/commands/core.py", line 235, in wrapped
    ret = await coro(*args, **kwargs)
  File "/home/lucassukeunkim/scuffed_discord_bot/bot.py", line 580, in pushtextfiles
    subprocess.run(["git", "fetch"], check=True)
  File "/usr/lib/python3.11/subprocess.py", line 550, in run
    stdout, stderr = process.communicate(input, timeout=timeout)
  File "/usr/lib/python3.11/subprocess.py", line 1199, in communicate
    self.wait()
  File "/usr/lib/python3.11/subprocess.py", line 1262, in wait
    return self._wait(timeout=timeout)
  File "/usr/lib/python3.11/subprocess.py", line 1997, in _wait
    (pid, sts) = self._try_wait(0)
  File "/usr/lib/python3.11/subprocess.py", line 1955, in _try_wait
    (pid, sts) = os.waitpid(self.pid, wait_flags)

[2025-02-16 08:37:13] [WARNING ] discord.gateway: Shard ID None heartbeat blocked for more than 540 seconds.
Loop thread traceback (most recent call last):
  File "/home/lucassukeunkim/scuffed_discord_bot/bot.py", line 682, in <module>
    bot.run(BOT_TOKEN, reconnect=True)
  File "/home/lucassukeunkim/myenv/lib/python3.11/site-packages/discord/client.py", line 869, in run
    asyncio.run(runner())
  File "/usr/lib/python3.11/asyncio/runners.py", line 190, in run
    return runner.run(main)
  File "/usr/lib/python3.11/asyncio/runners.py", line 118, in run
    return self._loop.run_until_complete(task)
  File "/usr/lib/python3.11/asyncio/base_events.py", line 640, in run_until_complete
    self.run_forever()
  File "/usr/lib/python3.11/asyncio/base_events.py", line 607, in run_forever
    self._run_once()
  File "/usr/lib/python3.11/asyncio/base_events.py", line 1922, in _run_once
    handle._run()
  File "/usr/lib/python3.11/asyncio/events.py", line 80, in _run
    self._context.run(self._callback, *self._args)
  File "/home/lucassukeunkim/myenv/lib/python3.11/site-packages/discord/client.py", line 449, in _run_event
    await coro(*args, **kwargs)
  File "/home/lucassukeunkim/scuffed_discord_bot/bot.py", line 48, in on_message
    await bot.process_commands(message)
  File "/home/lucassukeunkim/myenv/lib/python3.11/site-packages/discord/ext/commands/bot.py", line 1408, in process_commands
    await self.invoke(ctx)  # type: ignore
  File "/home/lucassukeunkim/myenv/lib/python3.11/site-packages/discord/ext/commands/bot.py", line 1366, in invoke
    await ctx.command.invoke(ctx)
  File "/home/lucassukeunkim/myenv/lib/python3.11/site-packages/discord/ext/commands/core.py", line 1029, in invoke
    await injected(*ctx.args, **ctx.kwargs)  # type: ignore
  File "/home/lucassukeunkim/myenv/lib/python3.11/site-packages/discord/ext/commands/core.py", line 235, in wrapped
    ret = await coro(*args, **kwargs)
  File "/home/lucassukeunkim/scuffed_discord_bot/bot.py", line 580, in pushtextfiles
    subprocess.run(["git", "fetch"], check=True)
  File "/usr/lib/python3.11/subprocess.py", line 550, in run
    stdout, stderr = process.communicate(input, timeout=timeout)
  File "/usr/lib/python3.11/subprocess.py", line 1199, in communicate
    self.wait()
  File "/usr/lib/python3.11/subprocess.py", line 1262, in wait
    return self._wait(timeout=timeout)
  File "/usr/lib/python3.11/subprocess.py", line 1997, in _wait
    (pid, sts) = self._try_wait(0)
  File "/usr/lib/python3.11/subprocess.py", line 1955, in _try_wait
    (pid, sts) = os.waitpid(self.pid, wait_flags)

[2025-02-16 08:37:23] [WARNING ] discord.gateway: Shard ID None heartbeat blocked for more than 550 seconds.
Loop thread traceback (most recent call last):
  File "/home/lucassukeunkim/scuffed_discord_bot/bot.py", line 682, in <module>
    bot.run(BOT_TOKEN, reconnect=True)
  File "/home/lucassukeunkim/myenv/lib/python3.11/site-packages/discord/client.py", line 869, in run
    asyncio.run(runner())
  File "/usr/lib/python3.11/asyncio/runners.py", line 190, in run
    return runner.run(main)
  File "/usr/lib/python3.11/asyncio/runners.py", line 118, in run
    return self._loop.run_until_complete(task)
  File "/usr/lib/python3.11/asyncio/base_events.py", line 640, in run_until_complete
    self.run_forever()
  File "/usr/lib/python3.11/asyncio/base_events.py", line 607, in run_forever
    self._run_once()
  File "/usr/lib/python3.11/asyncio/base_events.py", line 1922, in _run_once
    handle._run()
  File "/usr/lib/python3.11/asyncio/events.py", line 80, in _run
    self._context.run(self._callback, *self._args)
  File "/home/lucassukeunkim/myenv/lib/python3.11/site-packages/discord/client.py", line 449, in _run_event
    await coro(*args, **kwargs)
  File "/home/lucassukeunkim/scuffed_discord_bot/bot.py", line 48, in on_message
    await bot.process_commands(message)
  File "/home/lucassukeunkim/myenv/lib/python3.11/site-packages/discord/ext/commands/bot.py", line 1408, in process_commands
    await self.invoke(ctx)  # type: ignore
  File "/home/lucassukeunkim/myenv/lib/python3.11/site-packages/discord/ext/commands/bot.py", line 1366, in invoke
    await ctx.command.invoke(ctx)
  File "/home/lucassukeunkim/myenv/lib/python3.11/site-packages/discord/ext/commands/core.py", line 1029, in invoke
    await injected(*ctx.args, **ctx.kwargs)  # type: ignore
  File "/home/lucassukeunkim/myenv/lib/python3.11/site-packages/discord/ext/commands/core.py", line 235, in wrapped
    ret = await coro(*args, **kwargs)
  File "/home/lucassukeunkim/scuffed_discord_bot/bot.py", line 580, in pushtextfiles
    subprocess.run(["git", "fetch"], check=True)
  File "/usr/lib/python3.11/subprocess.py", line 550, in run
    stdout, stderr = process.communicate(input, timeout=timeout)
  File "/usr/lib/python3.11/subprocess.py", line 1199, in communicate
    self.wait()
  File "/usr/lib/python3.11/subprocess.py", line 1262, in wait
    return self._wait(timeout=timeout)
  File "/usr/lib/python3.11/subprocess.py", line 1997, in _wait
    (pid, sts) = self._try_wait(0)
  File "/usr/lib/python3.11/subprocess.py", line 1955, in _try_wait
    (pid, sts) = os.waitpid(self.pid, wait_flags)

Received disconnect from 140.82.114.3 port 22:11: Bye Bye
Disconnected from 140.82.114.3 port 22
fatal: Could not read from remote repository.

Please make sure you have the correct access rights
and the repository exists.
[2025-02-16 08:37:24] [INFO    ] discord.gateway: Shard ID None session has been invalidated.
[2025-02-16 08:37:30] [INFO    ] discord.gateway: Shard ID None has connected to Gateway (Session ID: 7b007d982298d419f58a2bd0d5f6e5d3).
Atyiseusseatyiseuss!
Atyiseusseatyiseuss!
session_stats.txt does not exist.
Task exception was never retrieved
future: <Task finished name='discord.py: on_message' coro=<Client._run_event() done, defined at /home/lucassukeunkim/myenv/lib/python3.11/site-packages/discord/client.py:441> exception=SystemExit()>
Traceback (most recent call last):
  File "/home/lucassukeunkim/myenv/lib/python3.11/site-packages/discord/client.py", line 869, in run
    asyncio.run(runner())
  File "/usr/lib/python3.11/asyncio/runners.py", line 190, in run
    return runner.run(main)
           ^^^^^^^^^^^^^^^^
  File "/usr/lib/python3.11/asyncio/runners.py", line 118, in run
    return self._loop.run_until_complete(task)
           ^^^^^^^^^^^^^^^^^^^^^^^^^^^^^^^^^^^
  File "/usr/lib/python3.11/asyncio/base_events.py", line 640, in run_until_complete
    self.run_forever()
  File "/usr/lib/python3.11/asyncio/base_events.py", line 607, in run_forever
    self._run_once()
  File "/usr/lib/python3.11/asyncio/base_events.py", line 1922, in _run_once
    handle._run()
  File "/usr/lib/python3.11/asyncio/events.py", line 80, in _run
    self._context.run(self._callback, *self._args)
  File "/home/lucassukeunkim/myenv/lib/python3.11/site-packages/discord/client.py", line 449, in _run_event
    await coro(*args, **kwargs)
  File "/home/lucassukeunkim/scuffed_discord_bot/bot.py", line 48, in on_message
    await bot.process_commands(message)
  File "/home/lucassukeunkim/myenv/lib/python3.11/site-packages/discord/ext/commands/bot.py", line 1408, in process_commands
    await self.invoke(ctx)  # type: ignore
    ^^^^^^^^^^^^^^^^^^^^^^
  File "/home/lucassukeunkim/myenv/lib/python3.11/site-packages/discord/ext/commands/bot.py", line 1366, in invoke
    await ctx.command.invoke(ctx)
  File "/home/lucassukeunkim/myenv/lib/python3.11/site-packages/discord/ext/commands/core.py", line 1029, in invoke
    await injected(*ctx.args, **ctx.kwargs)  # type: ignore
    ^^^^^^^^^^^^^^^^^^^^^^^^^^^^^^^^^^^^^^^
  File "/home/lucassukeunkim/myenv/lib/python3.11/site-packages/discord/ext/commands/core.py", line 235, in wrapped
    ret = await coro(*args, **kwargs)
          ^^^^^^^^^^^^^^^^^^^^^^^^^^^
  File "/home/lucassukeunkim/scuffed_discord_bot/bot.py", line 559, in update
    try:
         
SystemExit
[2025-02-16 08:39:05] [INFO    ] discord.client: logging in using static token
[2025-02-16 08:39:05] [INFO    ] discord.gateway: Shard ID None has connected to Gateway (Session ID: ea6fe067cb9056575ec7f9274fef5757).
[2025-02-16 08:41:05] [INFO    ] discord.voice_state: Connecting to voice...
[2025-02-16 08:41:05] [INFO    ] discord.voice_state: Starting voice handshake... (connection attempt 1)
[2025-02-16 08:41:05] [INFO    ] discord.voice_state: Voice handshake complete. Endpoint found: us-central6988.discord.media
[2025-02-16 08:41:05] [INFO    ] discord.voice_state: Voice connection complete.
[2025-02-16 08:41:08] [INFO    ] discord.player: ffmpeg process 103741 has not terminated. Waiting to terminate...
[2025-02-16 08:41:08] [INFO    ] discord.player: ffmpeg process 103741 should have terminated with a return code of -9.
[2025-02-16 08:41:09] [INFO    ] discord.player: ffmpeg process 103746 has not terminated. Waiting to terminate...
[2025-02-16 08:41:09] [INFO    ] discord.player: ffmpeg process 103746 should have terminated with a return code of -9.
[2025-02-16 08:41:10] [INFO    ] discord.player: ffmpeg process 103750 has not terminated. Waiting to terminate...
[2025-02-16 08:41:10] [INFO    ] discord.player: ffmpeg process 103750 should have terminated with a return code of -9.
[2025-02-16 08:41:11] [INFO    ] discord.player: ffmpeg process 103754 has not terminated. Waiting to terminate...
[2025-02-16 08:41:11] [INFO    ] discord.player: ffmpeg process 103754 should have terminated with a return code of -9.
[2025-02-16 08:41:12] [INFO    ] discord.player: ffmpeg process 103758 has not terminated. Waiting to terminate...
[2025-02-16 08:41:12] [INFO    ] discord.player: ffmpeg process 103758 should have terminated with a return code of -9.
[2025-02-16 08:41:13] [INFO    ] discord.player: ffmpeg process 103764 has not terminated. Waiting to terminate...
[2025-02-16 08:41:13] [INFO    ] discord.player: ffmpeg process 103764 should have terminated with a return code of -9.
[2025-02-16 08:41:13] [INFO    ] discord.player: ffmpeg process 103768 has not terminated. Waiting to terminate...
[2025-02-16 08:41:13] [INFO    ] discord.player: ffmpeg process 103768 should have terminated with a return code of -9.
[2025-02-16 08:52:18] [INFO    ] discord.voice_state: The voice handshake is being terminated for Channel ID 1339030117430853708 (Guild ID 134415388233433089)
Atyiseusseatyiseuss!
Finished playing: leads to sauce.ogg
Finished playing: rule #4.ogg
Finished playing: patbays.ogg
Finished playing: richard patrick2.ogg
Finished playing: fuck it up.ogg
Finished playing: stop it.ogg
Finished playing: stop it.ogg
session_stats.txt has been deleted successfully.
session_stats.txt does not exist.
Task exception was never retrieved
future: <Task finished name='discord.py: on_message' coro=<Client._run_event() done, defined at /home/lucassukeunkim/myenv/lib/python3.11/site-packages/discord/client.py:441> exception=SystemExit()>
Traceback (most recent call last):
  File "/home/lucassukeunkim/myenv/lib/python3.11/site-packages/discord/client.py", line 869, in run
    asyncio.run(runner())
  File "/usr/lib/python3.11/asyncio/runners.py", line 190, in run
    return runner.run(main)
           ^^^^^^^^^^^^^^^^
  File "/usr/lib/python3.11/asyncio/runners.py", line 118, in run
    return self._loop.run_until_complete(task)
           ^^^^^^^^^^^^^^^^^^^^^^^^^^^^^^^^^^^
  File "/usr/lib/python3.11/asyncio/base_events.py", line 640, in run_until_complete
    self.run_forever()
  File "/usr/lib/python3.11/asyncio/base_events.py", line 607, in run_forever
    self._run_once()
  File "/usr/lib/python3.11/asyncio/base_events.py", line 1922, in _run_once
    handle._run()
  File "/usr/lib/python3.11/asyncio/events.py", line 80, in _run
    self._context.run(self._callback, *self._args)
  File "/home/lucassukeunkim/myenv/lib/python3.11/site-packages/discord/client.py", line 449, in _run_event
    await coro(*args, **kwargs)
  File "/home/lucassukeunkim/scuffed_discord_bot/bot.py", line 48, in on_message
    await bot.process_commands(message)
  File "/home/lucassukeunkim/myenv/lib/python3.11/site-packages/discord/ext/commands/bot.py", line 1408, in process_commands
    await self.invoke(ctx)  # type: ignore
    ^^^^^^^^^^^^^^^^^^^^^^
  File "/home/lucassukeunkim/myenv/lib/python3.11/site-packages/discord/ext/commands/bot.py", line 1366, in invoke
    await ctx.command.invoke(ctx)
  File "/home/lucassukeunkim/myenv/lib/python3.11/site-packages/discord/ext/commands/core.py", line 1029, in invoke
    await injected(*ctx.args, **ctx.kwargs)  # type: ignore
    ^^^^^^^^^^^^^^^^^^^^^^^^^^^^^^^^^^^^^^^
  File "/home/lucassukeunkim/myenv/lib/python3.11/site-packages/discord/ext/commands/core.py", line 235, in wrapped
    ret = await coro(*args, **kwargs)
          ^^^^^^^^^^^^^^^^^^^^^^^^^^^
  File "/home/lucassukeunkim/scuffed_discord_bot/bot.py", line 539, in update
    await ctx.invoke(bot.get_command('restart'))
  File "/home/lucassukeunkim/myenv/lib/python3.11/site-packages/discord/ext/commands/context.py", line 337, in invoke
    return await command(self, *args, **kwargs)
           ^^^^^^^^^^^^^^^^^^^^^^^^^^^^^^^^^^^^
  File "/home/lucassukeunkim/myenv/lib/python3.11/site-packages/discord/ext/commands/core.py", line 590, in __call__
    return await self.callback(context, *args, **kwargs)  # type: ignore
           ^^^^^^^^^^^^^^^^^^^^^^^^^^^^^^^^^^^^^^^^^^^^^
  File "/home/lucassukeunkim/scuffed_discord_bot/bot.py", line 624, in restart
    subprocess.Popen(command, shell=True)
    ^^^^^^^^^^
SystemExit
[2025-02-16 09:10:38] [INFO    ] discord.client: logging in using static token
[2025-02-16 09:10:39] [INFO    ] discord.gateway: Shard ID None has connected to Gateway (Session ID: 0332fc5321e5cb7a9232a1b843fb12d1).
[2025-02-16 09:11:10] [INFO    ] discord.voice_state: Connecting to voice...
[2025-02-16 09:11:10] [INFO    ] discord.voice_state: Starting voice handshake... (connection attempt 1)
[2025-02-16 09:11:10] [INFO    ] discord.voice_state: Voice handshake complete. Endpoint found: us-central1194.discord.media
[2025-02-16 09:11:10] [INFO    ] discord.voice_state: Voice connection complete.
[2025-02-16 09:11:13] [INFO    ] discord.player: ffmpeg process 104029 has not terminated. Waiting to terminate...
[2025-02-16 09:11:13] [INFO    ] discord.player: ffmpeg process 104029 should have terminated with a return code of -9.
[2025-02-16 09:11:14] [INFO    ] discord.player: ffmpeg process 104032 has not terminated. Waiting to terminate...
[2025-02-16 09:11:14] [INFO    ] discord.player: ffmpeg process 104032 should have terminated with a return code of -9.
[2025-02-16 09:11:14] [INFO    ] discord.player: ffmpeg process 104036 has not terminated. Waiting to terminate...
[2025-02-16 09:11:14] [INFO    ] discord.player: ffmpeg process 104036 should have terminated with a return code of -9.
[2025-02-16 09:11:14] [INFO    ] discord.player: ffmpeg process 104040 has not terminated. Waiting to terminate...
[2025-02-16 09:11:14] [INFO    ] discord.player: ffmpeg process 104040 should have terminated with a return code of -9.
[2025-02-16 09:11:14] [INFO    ] discord.player: ffmpeg process 104044 has not terminated. Waiting to terminate...
[2025-02-16 09:11:14] [INFO    ] discord.player: ffmpeg process 104044 should have terminated with a return code of -9.
[2025-02-16 09:11:14] [INFO    ] discord.player: ffmpeg process 104050 has not terminated. Waiting to terminate...
[2025-02-16 09:11:14] [INFO    ] discord.player: ffmpeg process 104050 should have terminated with a return code of -9.
[2025-02-16 09:11:14] [INFO    ] discord.player: ffmpeg process 104054 has not terminated. Waiting to terminate...
[2025-02-16 09:11:14] [INFO    ] discord.player: ffmpeg process 104054 should have terminated with a return code of -9.
[2025-02-16 09:11:14] [INFO    ] discord.player: ffmpeg process 104056 has not terminated. Waiting to terminate...
[2025-02-16 09:11:14] [INFO    ] discord.player: ffmpeg process 104056 should have terminated with a return code of -9.
[2025-02-16 09:11:14] [INFO    ] discord.player: ffmpeg process 104060 has not terminated. Waiting to terminate...
[2025-02-16 09:11:14] [INFO    ] discord.player: ffmpeg process 104060 should have terminated with a return code of -9.
[2025-02-16 09:11:14] [INFO    ] discord.player: ffmpeg process 104064 has not terminated. Waiting to terminate...
[2025-02-16 09:11:14] [INFO    ] discord.player: ffmpeg process 104064 should have terminated with a return code of -9.
[2025-02-16 09:11:14] [INFO    ] discord.player: ffmpeg process 104068 has not terminated. Waiting to terminate...
[2025-02-16 09:11:14] [INFO    ] discord.player: ffmpeg process 104068 should have terminated with a return code of -9.
[2025-02-16 09:11:15] [INFO    ] discord.player: ffmpeg process 104072 has not terminated. Waiting to terminate...
[2025-02-16 09:11:15] [INFO    ] discord.player: ffmpeg process 104072 should have terminated with a return code of -9.
[2025-02-16 09:11:15] [INFO    ] discord.player: ffmpeg process 104076 has not terminated. Waiting to terminate...
[2025-02-16 09:11:15] [INFO    ] discord.player: ffmpeg process 104076 should have terminated with a return code of -9.
[2025-02-16 09:11:15] [INFO    ] discord.player: ffmpeg process 104080 has not terminated. Waiting to terminate...
[2025-02-16 09:11:15] [INFO    ] discord.player: ffmpeg process 104080 should have terminated with a return code of -9.
[2025-02-16 09:11:15] [INFO    ] discord.player: ffmpeg process 104084 has not terminated. Waiting to terminate...
[2025-02-16 09:11:15] [INFO    ] discord.player: ffmpeg process 104084 should have terminated with a return code of -9.
[2025-02-16 09:11:15] [INFO    ] discord.player: ffmpeg process 104088 has not terminated. Waiting to terminate...
[2025-02-16 09:11:15] [INFO    ] discord.player: ffmpeg process 104088 should have terminated with a return code of -9.
[2025-02-16 09:11:15] [INFO    ] discord.player: ffmpeg process 104092 has not terminated. Waiting to terminate...
[2025-02-16 09:11:15] [INFO    ] discord.player: ffmpeg process 104092 should have terminated with a return code of -9.
[2025-02-16 09:11:15] [INFO    ] discord.player: ffmpeg process 104096 has not terminated. Waiting to terminate...
[2025-02-16 09:11:15] [INFO    ] discord.player: ffmpeg process 104096 should have terminated with a return code of -9.
[2025-02-16 09:11:15] [INFO    ] discord.player: ffmpeg process 104100 has not terminated. Waiting to terminate...
[2025-02-16 09:11:15] [INFO    ] discord.player: ffmpeg process 104100 should have terminated with a return code of -9.
[2025-02-16 09:11:15] [INFO    ] discord.player: ffmpeg process 104104 has not terminated. Waiting to terminate...
[2025-02-16 09:11:15] [INFO    ] discord.player: ffmpeg process 104104 should have terminated with a return code of -9.
[2025-02-16 09:11:16] [INFO    ] discord.player: ffmpeg process 104110 has not terminated. Waiting to terminate...
[2025-02-16 09:11:16] [INFO    ] discord.player: ffmpeg process 104110 should have terminated with a return code of -9.
[2025-02-16 09:11:16] [INFO    ] discord.player: ffmpeg process 104114 has not terminated. Waiting to terminate...
[2025-02-16 09:11:16] [INFO    ] discord.player: ffmpeg process 104114 should have terminated with a return code of -9.
[2025-02-16 09:11:16] [INFO    ] discord.player: ffmpeg process 104118 has not terminated. Waiting to terminate...
[2025-02-16 09:11:16] [INFO    ] discord.player: ffmpeg process 104118 should have terminated with a return code of -9.
[2025-02-16 09:11:20] [INFO    ] discord.voice_state: The voice handshake is being terminated for Channel ID 1339030117430853708 (Guild ID 134415388233433089)
Atyiseusseatyiseuss!
Finished playing: keep out of here.ogg
Finished playing: rule #4 full.ogg
Finished playing: your lyrics.ogg
Finished playing: expert.ogg
Finished playing: stop it.ogg
Finished playing: are LAME.ogg
Finished playing: rosen.ogg
Finished playing: stop it.ogg
Finished playing: who.ogg
Finished playing: MAKE FOR THE GAP.ogg
Finished playing: here here.ogg
Finished playing: this is spider.ogg
Finished playing: beer.ogg
Finished playing: no way.ogg
Finished playing: dont.ogg
Finished playing: still i think.ogg
Finished playing: hobbits2.ogg
Finished playing: cock.ogg
Finished playing: fuck it up.ogg
Finished playing: another way in.ogg
Finished playing: did you hear.ogg
Finished playing: powers back.ogg
Finished playing: powers back.ogg
session_stats.txt has been deleted successfully.
session_stats.txt does not exist.
Task exception was never retrieved
future: <Task finished name='discord.py: on_message' coro=<Client._run_event() done, defined at /home/lucassukeunkim/myenv/lib/python3.11/site-packages/discord/client.py:441> exception=SystemExit()>
Traceback (most recent call last):
  File "/home/lucassukeunkim/myenv/lib/python3.11/site-packages/discord/client.py", line 869, in run
    asyncio.run(runner())
  File "/usr/lib/python3.11/asyncio/runners.py", line 190, in run
    return runner.run(main)
           ^^^^^^^^^^^^^^^^
  File "/usr/lib/python3.11/asyncio/runners.py", line 118, in run
    return self._loop.run_until_complete(task)
           ^^^^^^^^^^^^^^^^^^^^^^^^^^^^^^^^^^^
  File "/usr/lib/python3.11/asyncio/base_events.py", line 640, in run_until_complete
    self.run_forever()
  File "/usr/lib/python3.11/asyncio/base_events.py", line 607, in run_forever
    self._run_once()
  File "/usr/lib/python3.11/asyncio/base_events.py", line 1922, in _run_once
    handle._run()
  File "/usr/lib/python3.11/asyncio/events.py", line 80, in _run
    self._context.run(self._callback, *self._args)
  File "/home/lucassukeunkim/myenv/lib/python3.11/site-packages/discord/client.py", line 449, in _run_event
    await coro(*args, **kwargs)
  File "/home/lucassukeunkim/scuffed_discord_bot/bot.py", line 48, in on_message
    await bot.process_commands(message)
  File "/home/lucassukeunkim/myenv/lib/python3.11/site-packages/discord/ext/commands/bot.py", line 1408, in process_commands
    await self.invoke(ctx)  # type: ignore
    ^^^^^^^^^^^^^^^^^^^^^^
  File "/home/lucassukeunkim/myenv/lib/python3.11/site-packages/discord/ext/commands/bot.py", line 1366, in invoke
    await ctx.command.invoke(ctx)
  File "/home/lucassukeunkim/myenv/lib/python3.11/site-packages/discord/ext/commands/core.py", line 1029, in invoke
    await injected(*ctx.args, **ctx.kwargs)  # type: ignore
    ^^^^^^^^^^^^^^^^^^^^^^^^^^^^^^^^^^^^^^^
  File "/home/lucassukeunkim/myenv/lib/python3.11/site-packages/discord/ext/commands/core.py", line 235, in wrapped
    ret = await coro(*args, **kwargs)
          ^^^^^^^^^^^^^^^^^^^^^^^^^^^
  File "/home/lucassukeunkim/scuffed_discord_bot/bot.py", line 539, in update
    await ctx.invoke(bot.get_command('restart'))
  File "/home/lucassukeunkim/myenv/lib/python3.11/site-packages/discord/ext/commands/context.py", line 337, in invoke
    return await command(self, *args, **kwargs)
           ^^^^^^^^^^^^^^^^^^^^^^^^^^^^^^^^^^^^
  File "/home/lucassukeunkim/myenv/lib/python3.11/site-packages/discord/ext/commands/core.py", line 590, in __call__
    return await self.callback(context, *args, **kwargs)  # type: ignore
           ^^^^^^^^^^^^^^^^^^^^^^^^^^^^^^^^^^^^^^^^^^^^^
  File "/home/lucassukeunkim/scuffed_discord_bot/bot.py", line 626, in restart
    subprocess.Popen(command, shell=True)
    ^^^^^^^^^^
SystemExit
[2025-02-16 09:13:48] [INFO    ] discord.client: logging in using static token
[2025-02-16 09:13:49] [INFO    ] discord.gateway: Shard ID None has connected to Gateway (Session ID: 96c6998bbb1998d5a64027d2a9c8ca60).
Atyiseusseatyiseuss!
session_stats.txt does not exist.
Task exception was never retrieved
future: <Task finished name='discord.py: on_message' coro=<Client._run_event() done, defined at /home/lucassukeunkim/myenv/lib/python3.11/site-packages/discord/client.py:441> exception=SystemExit()>
Traceback (most recent call last):
  File "/home/lucassukeunkim/myenv/lib/python3.11/site-packages/discord/client.py", line 869, in run
    asyncio.run(runner())
  File "/usr/lib/python3.11/asyncio/runners.py", line 190, in run
    return runner.run(main)
           ^^^^^^^^^^^^^^^^
  File "/usr/lib/python3.11/asyncio/runners.py", line 118, in run
    return self._loop.run_until_complete(task)
           ^^^^^^^^^^^^^^^^^^^^^^^^^^^^^^^^^^^
  File "/usr/lib/python3.11/asyncio/base_events.py", line 640, in run_until_complete
    self.run_forever()
  File "/usr/lib/python3.11/asyncio/base_events.py", line 607, in run_forever
    self._run_once()
  File "/usr/lib/python3.11/asyncio/base_events.py", line 1922, in _run_once
    handle._run()
  File "/usr/lib/python3.11/asyncio/events.py", line 80, in _run
    self._context.run(self._callback, *self._args)
  File "/home/lucassukeunkim/myenv/lib/python3.11/site-packages/discord/client.py", line 449, in _run_event
    await coro(*args, **kwargs)
  File "/home/lucassukeunkim/scuffed_discord_bot/bot.py", line 48, in on_message
    await bot.process_commands(message)
  File "/home/lucassukeunkim/myenv/lib/python3.11/site-packages/discord/ext/commands/bot.py", line 1408, in process_commands
    await self.invoke(ctx)  # type: ignore
    ^^^^^^^^^^^^^^^^^^^^^^
  File "/home/lucassukeunkim/myenv/lib/python3.11/site-packages/discord/ext/commands/bot.py", line 1366, in invoke
    await ctx.command.invoke(ctx)
  File "/home/lucassukeunkim/myenv/lib/python3.11/site-packages/discord/ext/commands/core.py", line 1029, in invoke
    await injected(*ctx.args, **ctx.kwargs)  # type: ignore
    ^^^^^^^^^^^^^^^^^^^^^^^^^^^^^^^^^^^^^^^
  File "/home/lucassukeunkim/myenv/lib/python3.11/site-packages/discord/ext/commands/core.py", line 235, in wrapped
    ret = await coro(*args, **kwargs)
          ^^^^^^^^^^^^^^^^^^^^^^^^^^^
  File "/home/lucassukeunkim/scuffed_discord_bot/bot.py", line 539, in update
    await ctx.invoke(bot.get_command('restart'))
  File "/home/lucassukeunkim/myenv/lib/python3.11/site-packages/discord/ext/commands/context.py", line 337, in invoke
    return await command(self, *args, **kwargs)
           ^^^^^^^^^^^^^^^^^^^^^^^^^^^^^^^^^^^^
  File "/home/lucassukeunkim/myenv/lib/python3.11/site-packages/discord/ext/commands/core.py", line 590, in __call__
    return await self.callback(context, *args, **kwargs)  # type: ignore
           ^^^^^^^^^^^^^^^^^^^^^^^^^^^^^^^^^^^^^^^^^^^^^
  File "/home/lucassukeunkim/scuffed_discord_bot/bot.py", line 628, in restart
    sys.exit()
SystemExit
[2025-02-16 09:16:02] [INFO    ] discord.client: logging in using static token
[2025-02-16 09:16:03] [INFO    ] discord.gateway: Shard ID None has connected to Gateway (Session ID: 44c37a17c208417f55a40b06fcfcccf6).
